Workbook

Sheet DSSV
A1: STT | B1: CVHT | C1: Giáo vụ | D1: Tài khoản học | E1: Quyết định nhập học | F1: Ngày ban hành | G1: Thời gian đào tạo | H1: Kết thúc | I1: Cảnh báo | J1: MSV | K1: Họ và tên | L1: Họ | M1: Tên | N1: Ngày sinh | O1: Giới tính | P1: Khóa | Q1: Lớp | R1: Ngành | S1: Email | T1: SĐT | U1: MĐV | V1: Tên đơn vị | W1: Lớp | X1: Ngành | Y1: Đơn vị phối hợp (Mã đơn vị) | Z1: Tên đơn vị phối hợp (Theo uni) | AA1: Hình thức học | AB1: Trạng thái T12.2024 | AC1: Trạng thái T05.2025 | AD1: Trạng thái T12/2025 | AE1: Trạng thái dự kiến T05/2026 | AF1: Chi chú | AG1: EMAIL | AH1: SĐT | AI1: XÉT TN 3.2026
A2: =ROW()-1 -> 1 | B2: Trangnt | C2: Sangpn | D2: aicd | E2: 1301/2024/QĐ-ĐHM | F2: 05/04/2024 | G2: =(YEAR(H2)-YEAR(F2))*12 + MONTH(H2)-MONTH(F2) -> 72 | H2: 05/04/2030 | I2: =IF((H2-TODAY())<=0,"Kết thúc ĐT","Thời gian ĐT còn lại "&(H2-TODAY())&" ngày") -> Thời gian ĐT còn lại 1472 ngày | J2: 24C4702H1713 | K2: Cao Diệu Ái | L2: Cao Diệu | M2: Ái | N2: 27/12/1997 | O2: Nữ | P2: 21 | Q2: NDNVT621 | R2: Thương mại điện tử | S2: =VLOOKUP(D2, 'Mail+SDT'!A620:C2735, 2, 0) -> 24C4702H1713@students.hou.edu.vn | T2: =VLOOKUP(D2, 'Mail+SDT'!$A$2:$C$2117, 3, 0) -> 708239435 | U2: DNVT | V2: Trường Trung cấp Vạn Tường | W2: NDNVT621 | X2: Thương mại điện tử | Z2: Trường Trung cấp Vạn Tường | AA2: Trực tuyến | AB2: HT | AC2: HT | AD2: HT | AG2: {=_xludf.XLOOKUP(D2,'Mail+SDT'!A:A,'Mail+SDT'!B:B)} -> #NAME? | AH2: {=_xludf.XLOOKUP(D2,'Mail+SDT'!A:A,'Mail+SDT'!C:C)} -> #NAME? | AI2: {=_xludf.XLOOKUP(D2,'ETK 3.2026'!I:I,'ETK 3.2026'!AF:AF)} -> #NAME?
A3: =ROW()-1 -> 2 | B3: Trangnt | C3: Sangpn | D3: ailtv | E3: 1379/2024/QĐ-ĐHM | F3: 12/04/2024 | G3: =(YEAR(H3)-YEAR(F3))*12 + MONTH(H3)-MONTH(F3) -> 72 | H3: 12/04/2030 | I3: =IF((H3-TODAY())<=0,"Kết thúc ĐT","Thời gian ĐT còn lại "&(H3-TODAY())&" ngày") -> Thời gian ĐT còn lại 1479 ngày | J3: 24C4102H1911 | K3: Lê Thị Vị Ái | L3: Lê Thị Vị | M3: Ái | N3: 20/03/1985 | O3: Nữ | P3: 21 | Q3: ADNVT621 | R3: Kế toán | S3: =VLOOKUP(D3, 'Mail+SDT'!A366:C2481, 2, 0) -> 24C4102H1911@students.hou.edu.vn | T3: =VLOOKUP(D3, 'Mail+SDT'!$A$2:$C$2117, 3, 0) -> 907234003 | U3: DNVT | V3: Trường Trung cấp Vạn Tường | W3: ADNVT621 | X3: Kế toán | Z3: Trường Trung cấp Vạn Tường | AA3: Trực tuyến | AB3: HT | AC3: HT | AD3: HT | AG3: {=_xludf.XLOOKUP(D3,'Mail+SDT'!A:A,'Mail+SDT'!B:B)} -> #NAME? | AH3: {=_xludf.XLOOKUP(D3,'Mail+SDT'!A:A,'Mail+SDT'!C:C)} -> #NAME? | AI3: {=_xludf.XLOOKUP(D3,'ETK 3.2026'!I:I,'ETK 3.2026'!AF:AF)} -> #NAME?
A4: =ROW()-1 -> 3 | B4: Trangnt | C4: Sangpn | D4: anhbv008 | E4: 2983/2024/QĐ-ĐHM | F4: 26/07/2024 | G4: =(YEAR(H4)-YEAR(F4))*12 + MONTH(H4)-MONTH(F4) -> 72 | H4: 26/07/2030 | I4: =IF((H4-TODAY())<=0,"Kết thúc ĐT","Thời gian ĐT còn lại "&(H4-TODAY())&" ngày") -> Thời gian ĐT còn lại 1584 ngày | J4: 24C4702H4394 | K4: Bùi Vân Anh | L4: Bùi Vân | M4: Anh | N4: 18/04/1982 | O4: Nữ | P4: 21 | Q4: NDNVT321 | R4: Thương mại điện tử | S4: =VLOOKUP(D4, 'Mail+SDT'!A601:C2716, 2, 0) -> 24C4702H4394@students.hou.edu.vn | T4: =VLOOKUP(D4, 'Mail+SDT'!$A$2:$C$2117, 3, 0) -> 907180482 | U4: DNVT | V4: Trường Trung cấp Vạn Tường | W4: NDNVT321 | X4: Thương mại điện tử | Z4: Trường Trung cấp Vạn Tường | AA4: Trực tuyến | AB4: HT | AC4: HT | AD4: HT | AG4: {=_xludf.XLOOKUP(D4,'Mail+SDT'!A:A,'Mail+SDT'!B:B)} -> #NAME? | AH4: {=_xludf.XLOOKUP(D4,'Mail+SDT'!A:A,'Mail+SDT'!C:C)} -> #NAME? | AI4: {=_xludf.XLOOKUP(D4,'ETK 3.2026'!I:I,'ETK 3.2026'!AF:AF)} -> #NAME?
A5: =ROW()-1 -> 4 | B5: Trangnt | C5: Sangpn | D5: anhdlt | E5: 1301/2024/QĐ-ĐHM | F5: 05/04/2024 | G5: =(YEAR(H5)-YEAR(F5))*12 + MONTH(H5)-MONTH(F5) -> 72 | H5: 05/04/2030 | I5: =IF((H5-TODAY())<=0,"Kết thúc ĐT","Thời gian ĐT còn lại "&(H5-TODAY())&" ngày") -> Thời gian ĐT còn lại 1472 ngày | J5: 24C4102H1701 | K5: Đỗ Lê Thục Anh | L5: Đỗ Lê Thục | M5: Anh | N5: 02/03/2002 | O5: Nữ | P5: 21 | Q5: ADNVT221 | R5: Kế toán | S5: =VLOOKUP(D5, 'Mail+SDT'!A341:C2456, 2, 0) -> 24C4102H1701@students.hou.edu.vn | T5: =VLOOKUP(D5, 'Mail+SDT'!$A$2:$C$2117, 3, 0) -> 763715789 | U5: DNVT | V5: Trường Trung cấp Vạn Tường | W5: ADNVT221 | X5: Kế toán | Z5: Trường Trung cấp Vạn Tường | AA5: Trực tuyến | AB5: HT | AC5: HT | AD5: CBKL1 | AG5: {=_xludf.XLOOKUP(D5,'Mail+SDT'!A:A,'Mail+SDT'!B:B)} -> #NAME? | AH5: {=_xludf.XLOOKUP(D5,'Mail+SDT'!A:A,'Mail+SDT'!C:C)} -> #NAME? | AI5: {=_xludf.XLOOKUP(D5,'ETK 3.2026'!I:I,'ETK 3.2026'!AF:AF)} -> #NAME?
A6: =ROW()-1 -> 5 | B6: Trangnt | C6: Sangpn | D6: anhkh002 | E6: 2118/2022/QĐ-ĐHM | F6: 30/06/2022 | G6: =(YEAR(H6)-YEAR(F6))*12 + MONTH(H6)-MONTH(F6) -> 72 | H6: 30/06/2028 | I6: =IF((H6-TODAY())<=0,"Kết thúc ĐT","Thời gian ĐT còn lại "&(H6-TODAY())&" ngày") -> Thời gian ĐT còn lại 828 ngày | J6: 22C7102H2780 | K6: Kiều Hà Anh | L6: Kiều Hà | M6: Anh | N6: 03/08/1995 | O6: Nữ | P6: 17 | Q6: FDNVT417 | R6: Ngôn ngữ Anh | S6: =VLOOKUP(D6, 'Mail+SDT'!A288:C2403, 2, 0) -> kieuhaanh.153@gmail.com | T6: =VLOOKUP(D6, 'Mail+SDT'!$A$2:$C$2117, 3, 0) -> 917307873 | U6: DNVT | V6: Trường Trung cấp Vạn Tường | W6: FDNVT417 | X6: Ngôn ngữ Anh | Z6: Trường Trung cấp Vạn Tường | AA6: Trực tuyến | AB6: HT | AC6: HT | AD6: HT | AG6: {=_xludf.XLOOKUP(D6,'Mail+SDT'!A:A,'Mail+SDT'!B:B)} -> #NAME? | AH6: {=_xludf.XLOOKUP(D6,'Mail+SDT'!A:A,'Mail+SDT'!C:C)} -> #NAME? | AI6: {=_xludf.XLOOKUP(D6,'ETK 3.2026'!I:I,'ETK 3.2026'!Z:Z)} -> #NAME?
A7: =ROW()-1 -> 6 | B7: Trangnt | C7: Sangpn | D7: anhlt040 | E7: 839/2024/QĐ-ĐHM | F7: 08/03/2024 | G7: =(YEAR(H7)-YEAR(F7))*12 + MONTH(H7)-MONTH(F7) -> 72 | H7: 08/03/2030 | I7: =IF((H7-TODAY())<=0,"Kết thúc ĐT","Thời gian ĐT còn lại "&(H7-TODAY())&" ngày") -> Thời gian ĐT còn lại 1444 ngày | J7: 24C4502H1026 | K7: Lê Tuấn Anh | L7: Lê Tuấn | M7: Anh | N7: 11/12/1996 | O7: Nam | P7: 21 | Q7: DDNVT621 | R7: Tài chính - Ngân hàng | S7: =VLOOKUP(D7, 'Mail+SDT'!A581:C2696, 2, 0) -> 24C4502H1026@students.hou.edu.vn | T7: =VLOOKUP(D7, 'Mail+SDT'!$A$2:$C$2117, 3, 0) -> 984572573 | U7: DNVT | V7: Trường Trung cấp Vạn Tường | W7: DDNVT621 | X7: Tài chính - Ngân hàng | Z7: Trường Trung cấp Vạn Tường | AA7: Trực tuyến | AB7: HT | AC7: HT | AD7: CBKL1 | AG7: {=_xludf.XLOOKUP(D7,'Mail+SDT'!A:A,'Mail+SDT'!B:B)} -> #NAME? | AH7: {=_xludf.XLOOKUP(D7,'Mail+SDT'!A:A,'Mail+SDT'!C:C)} -> #NAME? | AI7: {=_xludf.XLOOKUP(D7,'ETK 3.2026'!I:I,'ETK 3.2026'!AF:AF)} -> #NAME?
A8: =ROW()-1 -> 7 | B8: Trangnt | C8: Sangpn | D8: anhlvh002 | E8: 839/2024/QĐ-ĐHM | F8: 08/03/2024 | G8: =(YEAR(H8)-YEAR(F8))*12 + MONTH(H8)-MONTH(F8) -> 72 | H8: 08/03/2030 | I8: =IF((H8-TODAY())<=0,"Kết thúc ĐT","Thời gian ĐT còn lại "&(H8-TODAY())&" ngày") -> Thời gian ĐT còn lại 1444 ngày | J8: 24C4202H1008 | K8: Lương Văn Hồng Anh | L8: Lương Văn Hồng | M8: Anh | N8: 12/12/1983 | O8: Nam | P8: 21 | Q8: BDNVT621 | R8: Quản trị kinh doanh | S8: =VLOOKUP(D8, 'Mail+SDT'!A471:C2586, 2, 0) -> 24C4202H1008@students.hou.edu.vn | T8: =VLOOKUP(D8, 'Mail+SDT'!$A$2:$C$2117, 3, 0) -> 938786192 | U8: DNVT | V8: Trường Trung cấp Vạn Tường | W8: BDNVT621 | X8: Quản trị kinh doanh | Z8: Trường Trung cấp Vạn Tường | AA8: Trực tuyến | AB8: HT | AC8: HT | AD8: CBKL1 | AE8: BTH | AF8: Thiếu QT học phí để QR | AG8: {=_xludf.XLOOKUP(D8,'Mail+SDT'!A:A,'Mail+SDT'!B:B)} -> #NAME? | AH8: {=_xludf.XLOOKUP(D8,'Mail+SDT'!A:A,'Mail+SDT'!C:C)} -> #NAME? | AI8: {=_xludf.XLOOKUP(D8,'ETK 3.2026'!I:I,'ETK 3.2026'!AF:AF)} -> #NAME?
A9: =ROW()-1 -> 8 | B9: Trangnt | C9: Sangpn | D9: anhnd036 | E9: 839/2024/QĐ-ĐHM | F9: 08/03/2024 | G9: =(YEAR(H9)-YEAR(F9))*12 + MONTH(H9)-MONTH(F9) -> 72 | H9: 08/03/2030 | I9: =IF((H9-TODAY())<=0,"Kết thúc ĐT","Thời gian ĐT còn lại "&(H9-TODAY())&" ngày") -> Thời gian ĐT còn lại 1444 ngày | J9: 24C4202H1014 | K9: Nguyễn Duy Anh | L9: Nguyễn Duy | M9: Anh | N9: 16/11/1992 | O9: Nam | P9: 21 | Q9: BDNVT621 | R9: Quản trị kinh doanh | S9: =VLOOKUP(D9, 'Mail+SDT'!A432:C2547, 2, 0) -> 24C4202H1014@students.hou.edu.vn | T9: =VLOOKUP(D9, 'Mail+SDT'!$A$2:$C$2117, 3, 0) -> 965702857 | U9: DNVT | V9: Trường Trung cấp Vạn Tường | W9: BDNVT621 | X9: Quản trị kinh doanh | Z9: Trường Trung cấp Vạn Tường | AA9: Trực tuyến | AB9: HT | AC9: HT | AD9: HT | AG9: {=_xludf.XLOOKUP(D9,'Mail+SDT'!A:A,'Mail+SDT'!B:B)} -> #NAME? | AH9: {=_xludf.XLOOKUP(D9,'Mail+SDT'!A:A,'Mail+SDT'!C:C)} -> #NAME? | AI9: {=_xludf.XLOOKUP(D9,'ETK 3.2026'!I:I,'ETK 3.2026'!AF:AF)} -> #NAME?
A10: =ROW()-1 -> 9 | B10: Trangnt | C10: Sangpn | D10: anhnh054 | E10: 2501/2024/QĐ-ĐHM | F10: 28/06/2024 | G10: =(YEAR(H10)-YEAR(F10))*12 + MONTH(H10)-MONTH(F10) -> 72 | H10: 28/06/2030 | I10: =IF((H10-TODAY())<=0,"Kết thúc ĐT","Thời gian ĐT còn lại "&(H10-TODAY())&" ngày") -> Thời gian ĐT còn lại 1556 ngày | J10: 24C4702H3654 | K10: Nguyễn Hoàng Anh | L10: Nguyễn Hoàng | M10: Anh | N10: 15/05/2000 | O10: Nam | P10: 21 | Q10: NDNVT621 | R10: Thương mại điện tử | S10: =VLOOKUP(D10, 'Mail+SDT'!A613:C2728, 2, 0) -> 24C4702H3654@students.hou.edu.vn | T10: =VLOOKUP(D10, 'Mail+SDT'!$A$2:$C$2117, 3, 0) -> 342604553 | U10: DNVT | V10: Trường Trung cấp Vạn Tường | W10: NDNVT621 | X10: Thương mại điện tử | Z10: Trường Trung cấp Vạn Tường | AA10: Trực tuyến | AB10: HT | AC10: HT | AD10: CBKL1 | AE10: BTH | AF10: Thiếu QT học phí để QR | AG10: {=_xludf.XLOOKUP(D10,'Mail+SDT'!A:A,'Mail+SDT'!B:B)} -> #NAME? | AH10: {=_xludf.XLOOKUP(D10,'Mail+SDT'!A:A,'Mail+SDT'!C:C)} -> #NAME? | AI10: {=_xludf.XLOOKUP(D10,'ETK 3.2026'!I:I,'ETK 3.2026'!AF:AF)} -> #NAME?
A11: =ROW()-1 -> 10 | B11: Trangnt | C11: Quynhtnn | D11: anhnm013 | E11: 1676/2024/QĐ-ĐHM | F11: 03/05/2024 | G11: =(YEAR(H11)-YEAR(F11))*12 + MONTH(H11)-MONTH(F11) -> 72 | H11: 03/05/2030 | I11: =IF((H11-TODAY())<=0,"Kết thúc ĐT","Thời gian ĐT còn lại "&(H11-TODAY())&" ngày") -> Thời gian ĐT còn lại 1500 ngày | J11: 24C1004D2525 | K11: Nguyễn Minh Anh | L11: Nguyễn Minh | M11: Anh | N11: 01/08/1998 | O11: Nam | P11: 21 | Q11: CDNP621 | R11: Công nghệ thông tin | S11: =VLOOKUP(D11, 'Mail+SDT'!A176:C2291, 2, 0) -> 24C1004D2525@students.hou.edu.vn | T11: =VLOOKUP(D11, 'Mail+SDT'!$A$2:$C$2117, 3, 0) -> 788354164 | U11: DNP | V11: Trung tâm Đại học Mở Hà Nội tại Đà Nẵng | W11: CDNP621 | X11: Công nghệ thông tin | Z11: Trung tâm Đại học Mở Hà Nội tại Đà Nẵng | AA11: Trực tuyến | AB11: HT | AC11: HT | AD11: HT | AG11: {=_xludf.XLOOKUP(D11,'Mail+SDT'!A:A,'Mail+SDT'!B:B)} -> #NAME? | AH11: {=_xludf.XLOOKUP(D11,'Mail+SDT'!A:A,'Mail+SDT'!C:C)} -> #NAME? | AI11: {=_xludf.XLOOKUP(D11,'ETK 3.2026'!I:I,'ETK 3.2026'!AF:AF)} -> #NAME?
A12: =ROW()-1 -> 11 | B12: Trangnt | C12: Sangpn | D12: anhnt097 | E12: 980/2022/QĐ-ĐHM | F12: 07/04/2022 | G12: =(YEAR(H12)-YEAR(F12))*12 + MONTH(H12)-MONTH(F12) -> 72 | H12: 07/04/2028 | I12: =IF((H12-TODAY())<=0,"Kết thúc ĐT","Thời gian ĐT còn lại "&(H12-TODAY())&" ngày") -> Thời gian ĐT còn lại 744 ngày | J12: 22C1002H1099 | K12: Nguyễn Tuấn Anh | L12: Nguyễn Tuấn | M12: Anh | N12: 18/04/1999 | O12: Nam | P12: 17 | Q12: CDNVT617 | R12: Công nghệ thông tin | S12: =VLOOKUP(D12, 'Mail+SDT'!A255:C2370, 2, 0) -> anhnguyen199a@gmail.com | T12: =VLOOKUP(D12, 'Mail+SDT'!$A$2:$C$2117, 3, 0) -> 339079133 | U12: DNVT | V12: Trường Trung cấp Vạn Tường | W12: CDNVT617 | X12: Công nghệ thông tin | Z12: Trường Trung cấp Vạn Tường | AA12: Trực tuyến | AB12: HT | AC12: HT | AD12: HT | AG12: {=_xludf.XLOOKUP(D12,'Mail+SDT'!A:A,'Mail+SDT'!B:B)} -> #NAME? | AH12: {=_xludf.XLOOKUP(D12,'Mail+SDT'!A:A,'Mail+SDT'!C:C)} -> #NAME? | AI12: {=_xludf.XLOOKUP(D12,'ETK 3.2026'!I:I,'ETK 3.2026'!Z:Z)} -> #NAME?
A13: =ROW()-1 -> 12 | B13: Trangnt | C13: Sangpn | D13: anhnt138 | E13: 1676/2024/QĐ-ĐHM | F13: 03/05/2024 | G13: =(YEAR(H13)-YEAR(F13))*12 + MONTH(H13)-MONTH(F13) -> 72 | H13: 03/05/2030 | I13: =IF((H13-TODAY())<=0,"Kết thúc ĐT","Thời gian ĐT còn lại "&(H13-TODAY())&" ngày") -> Thời gian ĐT còn lại 1500 ngày | J13: 24C4502H2431 | K13: Huỳnh Nguyễn Thanh Ân | L13: Huỳnh Nguyễn Thanh | M13: Ân | N13: 02/07/1989 | O13: Nam | P13: 21 | Q13: DDNVT621 | R13: Tài chính - Ngân hàng | S13: =VLOOKUP(D13, 'Mail+SDT'!A579:C2694, 2, 0) -> 24C4502H2431@students.hou.edu.vn | T13: =VLOOKUP(D13, 'Mail+SDT'!$A$2:$C$2117, 3, 0) -> 981827999 | U13: DNVT | V13: Trường Trung cấp Vạn Tường | W13: DDNVT621 | X13: Tài chính - Ngân hàng | Z13: Trường Trung cấp Vạn Tường | AA13: Trực tuyến | AB13: HT | AC13: HT | AD13: HT | AG13: {=_xludf.XLOOKUP(D13,'Mail+SDT'!A:A,'Mail+SDT'!B:B)} -> #NAME? | AH13: {=_xludf.XLOOKUP(D13,'Mail+SDT'!A:A,'Mail+SDT'!C:C)} -> #NAME? | AI13: {=_xludf.XLOOKUP(D13,'ETK 3.2026'!I:I,'ETK 3.2026'!AF:AF)} -> #NAME?
A14: =ROW()-1 -> 13 | B14: Trangnt | C14: Quynhtnn | D14: anhntk014 | E14: 2118/2022/QĐ-ĐHM | F14: 30/06/2022 | G14: =(YEAR(H14)-YEAR(F14))*12 + MONTH(H14)-MONTH(F14) -> 72 | H14: 30/06/2028 | I14: =IF((H14-TODAY())<=0,"Kết thúc ĐT","Thời gian ĐT còn lại "&(H14-TODAY())&" ngày") -> Thời gian ĐT còn lại 828 ngày | J14: 22C5004D2866 | K14: Nguyễn Thị Kim Anh | L14: Nguyễn Thị Kim | M14: Anh | N14: 11/02/1995 | O14: Nữ | P14: 17 | Q14: HDNP517 | R14: Luật | S14: =VLOOKUP(D14, 'Mail+SDT'!A79:C2194, 2, 0) -> nguyenkimanhkhct48@gmail.com | T14: =VLOOKUP(D14, 'Mail+SDT'!$A$2:$C$2117, 3, 0) -> 385627009 | U14: DNP | V14: Trung tâm Đại học Mở Hà Nội tại Đà Nẵng | W14: HDNP517 | X14: Luật | Z14: Trung tâm Đại học Mở Hà Nội tại Đà Nẵng | AA14: Trực tuyến | AB14: HT | AC14: HT | AD14: HTCT | AG14: {=_xludf.XLOOKUP(D14,'Mail+SDT'!A:A,'Mail+SDT'!B:B)} -> #NAME? | AH14: {=_xludf.XLOOKUP(D14,'Mail+SDT'!A:A,'Mail+SDT'!C:C)} -> #NAME? | AI14: {=_xludf.XLOOKUP(D14,'ETK 3.2026'!I:I,'ETK 3.2026'!AF:AF)} -> #NAME?
A15: =ROW()-1 -> 14 | B15: Trangnt | C15: Sangpn | D15: anhntn041 | E15: 1492/2022/QĐ-ĐHM | F15: 17/05/2022 | G15: =(YEAR(H15)-YEAR(F15))*12 + MONTH(H15)-MONTH(F15) -> 72 | H15: 17/05/2028 | I15: =IF((H15-TODAY())<=0,"Kết thúc ĐT","Thời gian ĐT còn lại "&(H15-TODAY())&" ngày") -> Thời gian ĐT còn lại 784 ngày | J15: 22C7102H1786 | K15: Nguyễn Thị Ngọc Anh | L15: Nguyễn Thị Ngọc | M15: Anh | N15: 09/06/1992 | O15: Nữ | P15: 17 | Q15: FDNVT617 | R15: Ngôn ngữ Anh | S15: =VLOOKUP(D15, 'Mail+SDT'!A312:C2427, 2, 0) -> janienguyen5480@gmail.com | T15: =VLOOKUP(D15, 'Mail+SDT'!$A$2:$C$2117, 3, 0) -> 359828779 | U15: DNVT | V15: Trường Trung cấp Vạn Tường | W15: FDNVT617 | X15: Ngôn ngữ Anh | Z15: Trường Trung cấp Vạn Tường | AA15: Trực tuyến | AB15: HT | AC15: HT | AD15: HT | AG15: {=_xludf.XLOOKUP(D15,'Mail+SDT'!A:A,'Mail+SDT'!B:B)} -> #NAME? | AH15: {=_xludf.XLOOKUP(D15,'Mail+SDT'!A:A,'Mail+SDT'!C:C)} -> #NAME? | AI15: {=_xludf.XLOOKUP(D15,'ETK 3.2026'!I:I,'ETK 3.2026'!Z:Z)} -> #NAME?
A16: =ROW()-1 -> 15 | B16: Trangnt | C16: Sangpn | D16: anhptp009 | E16: 2205/2024/QĐ-ĐHM | F16: 07/06/2024 | G16: =(YEAR(H16)-YEAR(F16))*12 + MONTH(H16)-MONTH(F16) -> 72 | H16: 07/06/2030 | I16: =IF((H16-TODAY())<=0,"Kết thúc ĐT","Thời gian ĐT còn lại "&(H16-TODAY())&" ngày") -> Thời gian ĐT còn lại 1535 ngày | J16: 24C4202H3171 | K16: Phạm Thị Phương Anh | L16: Phạm Thị Phương | M16: Anh | N16: 31/07/2000 | O16: Nữ | P16: 21 | Q16: BDNVT621 | R16: Quản trị kinh doanh | S16: =VLOOKUP(D16, 'Mail+SDT'!A454:C2569, 2, 0) -> 24C4202H3171@students.hou.edu.vn | T16: =VLOOKUP(D16, 'Mail+SDT'!$A$2:$C$2117, 3, 0) -> 797933442 | U16: DNVT | V16: Trường Trung cấp Vạn Tường | W16: BDNVT621 | X16: Quản trị kinh doanh | Z16: Trường Trung cấp Vạn Tường | AA16: Trực tuyến | AB16: HT | AC16: HT | AD16: CBKL1 | AE16: BTH | AF16: Thiếu QT học phí để QR | AG16: {=_xludf.XLOOKUP(D16,'Mail+SDT'!A:A,'Mail+SDT'!B:B)} -> #NAME? | AH16: {=_xludf.XLOOKUP(D16,'Mail+SDT'!A:A,'Mail+SDT'!C:C)} -> #NAME? | AI16: {=_xludf.XLOOKUP(D16,'ETK 3.2026'!I:I,'ETK 3.2026'!AF:AF)} -> #NAME?
A17: =ROW()-1 -> 16 | B17: Trangnt | C17: Sangpn | D17: anhtt041 | E17: 2118/2022/QĐ-ĐHM | F17: 30/06/2022 | G17: =(YEAR(H17)-YEAR(F17))*12 + MONTH(H17)-MONTH(F17) -> 72 | H17: 30/06/2028 | I17: =IF((H17-TODAY())<=0,"Kết thúc ĐT","Thời gian ĐT còn lại "&(H17-TODAY())&" ngày") -> Thời gian ĐT còn lại 828 ngày | J17: 22C5002H2819 | K17: Trần Tuấn Anh | L17: Trần Tuấn | M17: Anh | N17: 25/08/1988 | O17: Nam | P17: 17 | Q17: HDNVT617 | R17: Luật | S17: =VLOOKUP(D17, 'Mail+SDT'!A335:C2450, 2, 0) -> trantuananh25888@gmail.com | T17: =VLOOKUP(D17, 'Mail+SDT'!$A$2:$C$2117, 3, 0) -> 399907906 | U17: DNVT | V17: Trường Trung cấp Vạn Tường | W17: HDNVT617 | X17: Luật | Z17: Trường Trung cấp Vạn Tường | AA17: Trực tuyến | AB17: HT | AC17: HT | AD17: HT | AF17: TN 3.2026 | AG17: {=_xludf.XLOOKUP(D17,'Mail+SDT'!A:A,'Mail+SDT'!B:B)} -> #NAME? | AH17: {=_xludf.XLOOKUP(D17,'Mail+SDT'!A:A,'Mail+SDT'!C:C)} -> #NAME? | AI17: {=_xludf.XLOOKUP(D17,'ETK 3.2026'!I:I,'ETK 3.2026'!AF:AF)} -> #NAME?
A18: =ROW()-1 -> 17 | B18: Trangnt | C18: Sangpn | D18: anhtth007 | E18: 2118/2022/QĐ-ĐHM | F18: 30/06/2022 | G18: =(YEAR(H18)-YEAR(F18))*12 + MONTH(H18)-MONTH(F18) -> 72 | H18: 30/06/2028 | I18: =IF((H18-TODAY())<=0,"Kết thúc ĐT","Thời gian ĐT còn lại "&(H18-TODAY())&" ngày") -> Thời gian ĐT còn lại 828 ngày | J18: 22C7102H2808 | K18: Trần Thị Hồng Anh | L18: Trần Thị Hồng | M18: Anh | N18: 11/09/1989 | O18: Nữ | P18: 17 | Q18: FDNVT617 | R18: Ngôn ngữ Anh | S18: =VLOOKUP(D18, 'Mail+SDT'!A299:C2414, 2, 0) -> honganh1109@gmail.com | T18: =VLOOKUP(D18, 'Mail+SDT'!$A$2:$C$2117, 3, 0) -> 939499577 | U18: DNVT | V18: Trường Trung cấp Vạn Tường | W18: FDNVT617 | X18: Ngôn ngữ Anh | Z18: Trường Trung cấp Vạn Tường | AA18: Trực tuyến | AB18: HT | AC18: HT | AD18: HT | AG18: {=_xludf.XLOOKUP(D18,'Mail+SDT'!A:A,'Mail+SDT'!B:B)} -> #NAME? | AH18: {=_xludf.XLOOKUP(D18,'Mail+SDT'!A:A,'Mail+SDT'!C:C)} -> #NAME? | AI18: {=_xludf.XLOOKUP(D18,'ETK 3.2026'!I:I,'ETK 3.2026'!AF:AF)} -> #NAME?
A19: =ROW()-1 -> 18 | B19: Trangnt | C19: Sangpn | D19: anhttn012 | E19: 2118/2022/QĐ-ĐHM | F19: 30/06/2022 | G19: =(YEAR(H19)-YEAR(F19))*12 + MONTH(H19)-MONTH(F19) -> 72 | H19: 30/06/2028 | I19: =IF((H19-TODAY())<=0,"Kết thúc ĐT","Thời gian ĐT còn lại "&(H19-TODAY())&" ngày") -> Thời gian ĐT còn lại 828 ngày | J19: 22C4502H2862 | K19: Trương Thị Ngọc Anh | L19: Trương Thị Ngọc | M19: Anh | N19: 30/08/1995 | O19: Nữ | P19: 17 | Q19: DDNVT617 | R19: Tài chính - Ngân hàng | S19: =VLOOKUP(D19, 'Mail+SDT'!A264:C2379, 2, 0) -> ngocanh102109@gmail.com | T19: =VLOOKUP(D19, 'Mail+SDT'!$A$2:$C$2117, 3, 0) -> 968310395 | U19: DNVT | V19: Trường Trung cấp Vạn Tường | W19: DDNVT617 | X19: Tài chính - Ngân hàng | Z19: Trường Trung cấp Vạn Tường | AA19: Trực tuyến | AB19: HT | AC19: HT | AD19: HT | AF19: TN 3.2026 | AG19: {=_xludf.XLOOKUP(D19,'Mail+SDT'!A:A,'Mail+SDT'!B:B)} -> #NAME? | AH19: {=_xludf.XLOOKUP(D19,'Mail+SDT'!A:A,'Mail+SDT'!C:C)} -> #NAME? | AI19: {=_xludf.XLOOKUP(D19,'ETK 3.2026'!I:I,'ETK 3.2026'!AF:AF)} -> #NAME?
A20: =ROW()-1 -> 19 | B20: Trangnt | C20: Sangpn | D20: anhttp012 | E20: 1301/2024/QĐ-ĐHM | F20: 05/04/2024 | G20: =(YEAR(H20)-YEAR(F20))*12 + MONTH(H20)-MONTH(F20) -> 72 | H20: 05/04/2030 | I20: =IF((H20-TODAY())<=0,"Kết thúc ĐT","Thời gian ĐT còn lại "&(H20-TODAY())&" ngày") -> Thời gian ĐT còn lại 1472 ngày | J20: 24C4702H1717 | K20: Trần Thị Phương Anh | L20: Trần Thị Phương | M20: Anh | N20: 10/09/1996 | O20: Nữ | P20: 21 | Q20: NDNVT621 | R20: Thương mại điện tử | S20: =VLOOKUP(D20, 'Mail+SDT'!A616:C2731, 2, 0) -> 24C4702H1717@students.hou.edu.vn | T20: =VLOOKUP(D20, 'Mail+SDT'!$A$2:$C$2117, 3, 0) -> 7022119496 | U20: DNVT | V20: Trường Trung cấp Vạn Tường | W20: NDNVT621 | X20: Thương mại điện tử | Z20: Trường Trung cấp Vạn Tường | AA20: Trực tuyến | AB20: HT | AC20: HT | AD20: CBKL1 | AG20: {=_xludf.XLOOKUP(D20,'Mail+SDT'!A:A,'Mail+SDT'!B:B)} -> #NAME? | AH20: {=_xludf.XLOOKUP(D20,'Mail+SDT'!A:A,'Mail+SDT'!C:C)} -> #NAME? | AI20: {=_xludf.XLOOKUP(D20,'ETK 3.2026'!I:I,'ETK 3.2026'!AF:AF)} -> #NAME?
A21: =ROW()-1 -> 20 | B21: Trangnt | C21: Sangpn | D21: anhttt011 | E21: 1301/2024/QĐ-ĐHM | F21: 05/04/2024 | G21: =(YEAR(H21)-YEAR(F21))*12 + MONTH(H21)-MONTH(F21) -> 72 | H21: 05/04/2030 | I21: =IF((H21-TODAY())<=0,"Kết thúc ĐT","Thời gian ĐT còn lại "&(H21-TODAY())&" ngày") -> Thời gian ĐT còn lại 1472 ngày | J21: 24C4202H1685 | K21: Trần Thị Tú Anh | L21: Trần Thị Tú | M21: Anh | N21: 15/07/1990 | O21: Nữ | P21: 21 | Q21: BDNVT421 | R21: Quản trị kinh doanh | S21: =VLOOKUP(D21, 'Mail+SDT'!A412:C2527, 2, 0) -> 24C4202H1685@students.hou.edu.vn | T21: =VLOOKUP(D21, 'Mail+SDT'!$A$2:$C$2117, 3, 0) -> 973689642 | U21: DNVT | V21: Trường Trung cấp Vạn Tường | W21: BDNVT421 | X21: Quản trị kinh doanh | Z21: Trường Trung cấp Vạn Tường | AA21: Trực tuyến | AB21: HT | AC21: HT | AD21: HT | AG21: {=_xludf.XLOOKUP(D21,'Mail+SDT'!A:A,'Mail+SDT'!B:B)} -> #NAME? | AH21: {=_xludf.XLOOKUP(D21,'Mail+SDT'!A:A,'Mail+SDT'!C:C)} -> #NAME? | AI21: {=_xludf.XLOOKUP(D21,'ETK 3.2026'!I:I,'ETK 3.2026'!AF:AF)} -> #NAME?
A22: =ROW()-1 -> 21 | B22: Trangnt | C22: Sangpn | D22: anhttv014 | E22: 1492/2022/QĐ-ĐHM | F22: 17/05/2022 | G22: =(YEAR(H22)-YEAR(F22))*12 + MONTH(H22)-MONTH(F22) -> 72 | H22: 17/05/2028 | I22: =IF((H22-TODAY())<=0,"Kết thúc ĐT","Thời gian ĐT còn lại "&(H22-TODAY())&" ngày") -> Thời gian ĐT còn lại 784 ngày | J22: 22C7102H1806 | K22: Trịnh Thị Vân Anh | L22: Trịnh Thị Vân | M22: Anh | N22: 15/05/1997 | O22: Nữ | P22: 17 | Q22: FDNVT617 | R22: Ngôn ngữ Anh | S22: =VLOOKUP(D22, 'Mail+SDT'!A311:C2426, 2, 0) -> trang051597@gmail.com | T22: =VLOOKUP(D22, 'Mail+SDT'!$A$2:$C$2117, 3, 0) -> 964067039 | U22: DNVT | V22: Trường Trung cấp Vạn Tường | W22: FDNVT617 | X22: Ngôn ngữ Anh | Z22: Trường Trung cấp Vạn Tường | AA22: Trực tuyến | AB22: HT | AC22: HT | AD22: HT | AF22: TN 3.2026 | AG22: {=_xludf.XLOOKUP(D22,'Mail+SDT'!A:A,'Mail+SDT'!B:B)} -> #NAME? | AH22: {=_xludf.XLOOKUP(D22,'Mail+SDT'!A:A,'Mail+SDT'!C:C)} -> #NAME? | AI22: {=_xludf.XLOOKUP(D22,'ETK 3.2026'!I:I,'ETK 3.2026'!AF:AF)} -> #NAME?
A23: =ROW()-1 -> 22 | B23: Trangnt | C23: Quynhtnn | D23: anhvtn006 | E23: 593/2022/QĐ-ĐHM | F23: 04/03/2022 | G23: =(YEAR(H23)-YEAR(F23))*12 + MONTH(H23)-MONTH(F23) -> 72 | H23: 04/03/2028 | I23: =IF((H23-TODAY())<=0,"Kết thúc ĐT","Thời gian ĐT còn lại "&(H23-TODAY())&" ngày") -> Thời gian ĐT còn lại 710 ngày | J23: 22C4104D0243 | K23: Võ Thị Ngọc Anh | L23: Võ Thị Ngọc | M23: Anh | N23: 19/12/1995 | O23: Nữ | P23: 17 | Q23: ADNP417 | R23: Kế toán | S23: =VLOOKUP(D23, 'Mail+SDT'!A22:C2137, 2, 0) -> ngocanh.vo1912@gmail.com | T23: =VLOOKUP(D23, 'Mail+SDT'!$A$2:$C$2117, 3, 0) -> 973700618 | U23: DNP | V23: Trung tâm Đại học Mở Hà Nội tại Đà Nẵng | W23: ADNP417 | X23: Kế toán | Z23: Trung tâm Đại học Mở Hà Nội tại Đà Nẵng | AA23: Trực tuyến | AB23: HT | AC23: HT | AD23: HT | AG23: {=_xludf.XLOOKUP(D23,'Mail+SDT'!A:A,'Mail+SDT'!B:B)} -> #NAME? | AH23: {=_xludf.XLOOKUP(D23,'Mail+SDT'!A:A,'Mail+SDT'!C:C)} -> #NAME? | AI23: {=_xludf.XLOOKUP(D23,'ETK 3.2026'!I:I,'ETK 3.2026'!Z:Z)} -> #NAME?
A24: =ROW()-1 -> 23 | B24: Trangnt | C24: Sangpn | D24: anhvv009 | E24: 2118/2022/QĐ-ĐHM | F24: 30/06/2022 | G24: =(YEAR(H24)-YEAR(F24))*12 + MONTH(H24)-MONTH(F24) -> 72 | H24: 30/06/2028 | I24: =IF((H24-TODAY())<=0,"Kết thúc ĐT","Thời gian ĐT còn lại "&(H24-TODAY())&" ngày") -> Thời gian ĐT còn lại 828 ngày | J24: 22C5002H2830 | K24: Võ Vân Anh | L24: Võ Vân | M24: Anh | N24: 08/10/2003 | O24: Nữ | P24: 17 | Q24: HDNVT617 | R24: Luật | S24: =VLOOKUP(D24, 'Mail+SDT'!A337:C2452, 2, 0) -> vananh0810tb@gmail.com | T24: =VLOOKUP(D24, 'Mail+SDT'!$A$2:$C$2117, 3, 0) -> 862781857 | U24: DNVT | V24: Trường Trung cấp Vạn Tường | W24: HDNVT617 | X24: Luật | Z24: Trường Trung cấp Vạn Tường | AA24: Trực tuyến | AB24: HT | AC24: HT | AD24: HT | AG24: {=_xludf.XLOOKUP(D24,'Mail+SDT'!A:A,'Mail+SDT'!B:B)} -> #NAME? | AH24: {=_xludf.XLOOKUP(D24,'Mail+SDT'!A:A,'Mail+SDT'!C:C)} -> #NAME? | AI24: {=_xludf.XLOOKUP(D24,'ETK 3.2026'!I:I,'ETK 3.2026'!Z:Z)} -> #NAME?
A25: =ROW()-1 -> 24 | B25: Trangnt | C25: Sangpn | D25: anhvv012 | E25: 2501/2024/QĐ-ĐHM | F25: 28/06/2024 | G25: =(YEAR(H25)-YEAR(F25))*12 + MONTH(H25)-MONTH(F25) -> 72 | H25: 28/06/2030 | I25: =IF((H25-TODAY())<=0,"Kết thúc ĐT","Thời gian ĐT còn lại "&(H25-TODAY())&" ngày") -> Thời gian ĐT còn lại 1556 ngày | J25: 24C4202H3565 | K25: Võ Vân Anh | L25: Võ Vân | M25: Anh | N25: 05/05/1998 | O25: Nữ | P25: 21 | Q25: BDNVT621 | R25: Quản trị kinh doanh | S25: =VLOOKUP(D25, 'Mail+SDT'!A451:C2566, 2, 0) -> 24C4202H3565@students.hou.edu.vn | T25: =VLOOKUP(D25, 'Mail+SDT'!$A$2:$C$2117, 3, 0) -> 985884513 | U25: DNVT | V25: Trường Trung cấp Vạn Tường | W25: BDNVT621 | X25: Quản trị kinh doanh | Z25: Trường Trung cấp Vạn Tường | AA25: Trực tuyến | AB25: HT | AC25: HT | AD25: CBKL1 | AE25: BTH | AF25: Thiếu QT học phí để QR | AG25: {=_xludf.XLOOKUP(D25,'Mail+SDT'!A:A,'Mail+SDT'!B:B)} -> #NAME? | AH25: {=_xludf.XLOOKUP(D25,'Mail+SDT'!A:A,'Mail+SDT'!C:C)} -> #NAME? | AI25: {=_xludf.XLOOKUP(D25,'ETK 3.2026'!I:I,'ETK 3.2026'!AF:AF)} -> #NAME?
A26: =ROW()-1 -> 25 | B26: Trangnt | C26: Quynhtnn | D26: anntt017 | E26: 2983/2024/QĐ-ĐHM | F26: 26/07/2024 | G26: =(YEAR(H26)-YEAR(F26))*12 + MONTH(H26)-MONTH(F26) -> 72 | H26: 26/07/2030 | I26: =IF((H26-TODAY())<=0,"Kết thúc ĐT","Thời gian ĐT còn lại "&(H26-TODAY())&" ngày") -> Thời gian ĐT còn lại 1584 ngày | J26: 24C1004D4405 | K26: Nguyễn Thiên Thuận An | L26: Nguyễn Thiên Thuận | M26: An | N26: 08/05/1996 | O26: Nữ | P26: 21 | Q26: CDNP321 | R26: Công nghệ thông tin | S26: =VLOOKUP(D26, 'Mail+SDT'!A163:C2278, 2, 0) -> 24C1004D4405@students.hou.edu.vn | T26: =VLOOKUP(D26, 'Mail+SDT'!$A$2:$C$2117, 3, 0) -> 338740898 | U26: DNP | V26: Trung tâm Đại học Mở Hà Nội tại Đà Nẵng | W26: CDNP321 | X26: Công nghệ thông tin | Z26: Trung tâm Đại học Mở Hà Nội tại Đà Nẵng | AA26: Trực tuyến | AB26: HT | AC26: HT | AD26: CBKL1 | AG26: {=_xludf.XLOOKUP(D26,'Mail+SDT'!A:A,'Mail+SDT'!B:B)} -> #NAME? | AH26: {=_xludf.XLOOKUP(D26,'Mail+SDT'!A:A,'Mail+SDT'!C:C)} -> #NAME? | AI26: {=_xludf.XLOOKUP(D26,'ETK 3.2026'!I:I,'ETK 3.2026'!AF:AF)} -> #NAME?
A27: =ROW()-1 -> 26 | B27: Trangnt | C27: Sangpn | D27: annv014 | E27: 2205/2024/QĐ-ĐHM | F27: 07/06/2024 | G27: =(YEAR(H27)-YEAR(F27))*12 + MONTH(H27)-MONTH(F27) -> 72 | H27: 07/06/2030 | I27: =IF((H27-TODAY())<=0,"Kết thúc ĐT","Thời gian ĐT còn lại "&(H27-TODAY())&" ngày") -> Thời gian ĐT còn lại 1535 ngày | J27: 24C4502H3261 | K27: Nguyễn Văn An | L27: Nguyễn Văn | M27: An | N27: 25/03/1993 | O27: Nam | P27: 21 | Q27: DDNVT621 | R27: Tài chính - Ngân hàng | S27: =VLOOKUP(D27, 'Mail+SDT'!A593:C2708, 2, 0) -> 24C4502H3261@students.hou.edu.vn | T27: =VLOOKUP(D27, 'Mail+SDT'!$A$2:$C$2117, 3, 0) -> 978935845 | U27: DNVT | V27: Trường Trung cấp Vạn Tường | W27: DDNVT621 | X27: Tài chính - Ngân hàng | Z27: Trường Trung cấp Vạn Tường | AA27: Trực tuyến | AB27: HT | AC27: HT | AD27: HT | AG27: {=_xludf.XLOOKUP(D27,'Mail+SDT'!A:A,'Mail+SDT'!B:B)} -> #NAME? | AH27: {=_xludf.XLOOKUP(D27,'Mail+SDT'!A:A,'Mail+SDT'!C:C)} -> #NAME? | AI27: {=_xludf.XLOOKUP(D27,'ETK 3.2026'!I:I,'ETK 3.2026'!AF:AF)} -> #NAME?
A28: =ROW()-1 -> 27 | B28: Trangnt | C28: Sangpn | D28: anptv | E28: 1676/2024/QĐ-ĐHM | F28: 03/05/2024 | G28: =(YEAR(H28)-YEAR(F28))*12 + MONTH(H28)-MONTH(F28) -> 72 | H28: 03/05/2030 | I28: =IF((H28-TODAY())<=0,"Kết thúc ĐT","Thời gian ĐT còn lại "&(H28-TODAY())&" ngày") -> Thời gian ĐT còn lại 1500 ngày | J28: 24C4202H2427 | K28: Phan Thị Vĩnh An | L28: Phan Thị Vĩnh | M28: An | N28: 13/07/2005 | O28: Nữ | P28: 21 | Q28: BDNVT621 | R28: Quản trị kinh doanh | S28: =VLOOKUP(D28, 'Mail+SDT'!A466:C2581, 2, 0) -> 24C4202H2427@students.hou.edu.vn | T28: =VLOOKUP(D28, 'Mail+SDT'!$A$2:$C$2117, 3, 0) -> 828409986 | U28: DNVT | V28: Trường Trung cấp Vạn Tường | W28: BDNVT621 | X28: Quản trị kinh doanh | Z28: Trường Trung cấp Vạn Tường | AA28: Trực tuyến | AB28: HT | AC28: HT | AD28: HT | AG28: {=_xludf.XLOOKUP(D28,'Mail+SDT'!A:A,'Mail+SDT'!B:B)} -> #NAME? | AH28: {=_xludf.XLOOKUP(D28,'Mail+SDT'!A:A,'Mail+SDT'!C:C)} -> #NAME? | AI28: {=_xludf.XLOOKUP(D28,'ETK 3.2026'!I:I,'ETK 3.2026'!AF:AF)} -> #NAME?
A29: =ROW()-1 -> 28 | B29: Trangnt | C29: Quynhtnn | D29: antn002 | E29: 2118/2022/QĐ-ĐHM | F29: 30/06/2022 | G29: =(YEAR(H29)-YEAR(F29))*12 + MONTH(H29)-MONTH(F29) -> 72 | H29: 30/06/2028 | I29: =IF((H29-TODAY())<=0,"Kết thúc ĐT","Thời gian ĐT còn lại "&(H29-TODAY())&" ngày") -> Thời gian ĐT còn lại 828 ngày | J29: 22C5104D2873 | K29: Trần Ngọc An | L29: Trần Ngọc | M29: An | N29: 12/06/1987 | O29: Nam | P29: 17 | Q29: EDNP617 | R29: Luật kinh tế | S29: =VLOOKUP(D29, 'Mail+SDT'!A63:C2178, 2, 0) -> ngocanqn87@gmail.com | T29: =VLOOKUP(D29, 'Mail+SDT'!$A$2:$C$2117, 3, 0) -> 905295983 | U29: DNP | V29: Trung tâm Đại học Mở Hà Nội tại Đà Nẵng | W29: EDNP617 | X29: Luật kinh tế | Z29: Trung tâm Đại học Mở Hà Nội tại Đà Nẵng | AA29: Trực tuyến | AB29: HT | AC29: HT | AD29: HT | AF29: TN 3.2026 | AG29: {=_xludf.XLOOKUP(D29,'Mail+SDT'!A:A,'Mail+SDT'!B:B)} -> #NAME? | AH29: {=_xludf.XLOOKUP(D29,'Mail+SDT'!A:A,'Mail+SDT'!C:C)} -> #NAME? | AI29: {=_xludf.XLOOKUP(D29,'ETK 3.2026'!I:I,'ETK 3.2026'!AF:AF)} -> #NAME?
A30: =ROW()-1 -> 29 | B30: Trangnt | C30: Quynhtnn | D30: baobtg | E30: 4768/2023/QĐ-ĐHM | F30: 15/12/2023 | G30: =(YEAR(H30)-YEAR(F30))*12 + MONTH(H30)-MONTH(F30) -> 72 | H30: 15/12/2029 | I30: =IF((H30-TODAY())<=0,"Kết thúc ĐT","Thời gian ĐT còn lại "&(H30-TODAY())&" ngày") -> Thời gian ĐT còn lại 1361 ngày | J30: 23C1004D5964 | K30: Bùi Trà Gia Bảo | L30: Bùi Trà Gia | M30: Bảo | N30: 20/07/1998 | O30: Nam | P30: 21 | Q30: CDNP621 | R30: Công nghệ thông tin | S30: =VLOOKUP(D30, 'Mail+SDT'!A179:C2294, 2, 0) -> 23C1004D5964@students.hou.edu.vn | T30: =VLOOKUP(D30, 'Mail+SDT'!$A$2:$C$2117, 3, 0) -> 855454911 | U30: DNP | V30: Trung tâm Đại học Mở Hà Nội tại Đà Nẵng | W30: CDNP621 | X30: Công nghệ thông tin | Z30: Trung tâm Đại học Mở Hà Nội tại Đà Nẵng | AA30: Trực tuyến | AB30: HT | AC30: HT | AD30: HT | AG30: {=_xludf.XLOOKUP(D30,'Mail+SDT'!A:A,'Mail+SDT'!B:B)} -> #NAME? | AH30: {=_xludf.XLOOKUP(D30,'Mail+SDT'!A:A,'Mail+SDT'!C:C)} -> #NAME? | AI30: {=_xludf.XLOOKUP(D30,'ETK 3.2026'!I:I,'ETK 3.2026'!AF:AF)} -> #NAME?
A31: =ROW()-1 -> 30 | B31: Trangnt | C31: Sangpn | D31: baodg002 | E31: 1676/2024/QĐ-ĐHM | F31: 03/05/2024 | G31: =(YEAR(H31)-YEAR(F31))*12 + MONTH(H31)-MONTH(F31) -> 72 | H31: 03/05/2030 | I31: =IF((H31-TODAY())<=0,"Kết thúc ĐT","Thời gian ĐT còn lại "&(H31-TODAY())&" ngày") -> Thời gian ĐT còn lại 1500 ngày | J31: 24C1002H2398 | K31: Dương Gia Bảo | L31: Dương Gia | M31: Bảo | N31: 14/04/2002 | O31: Nam | P31: 21 | Q31: CDNVT621 | R31: Công nghệ thông tin | S31: =VLOOKUP(D31, 'Mail+SDT'!A544:C2659, 2, 0) -> 24C1002H2398@students.hou.edu.vn | T31: =VLOOKUP(D31, 'Mail+SDT'!$A$2:$C$2117, 3, 0) -> 981701321 | U31: DNVT | V31: Trường Trung cấp Vạn Tường | W31: CDNVT621 | X31: Công nghệ thông tin | Z31: Trường Trung cấp Vạn Tường | AA31: Trực tuyến | AB31: HT | AC31: HT | AD31: HT | AG31: {=_xludf.XLOOKUP(D31,'Mail+SDT'!A:A,'Mail+SDT'!B:B)} -> #NAME? | AH31: {=_xludf.XLOOKUP(D31,'Mail+SDT'!A:A,'Mail+SDT'!C:C)} -> #NAME? | AI31: {=_xludf.XLOOKUP(D31,'ETK 3.2026'!I:I,'ETK 3.2026'!AF:AF)} -> #NAME?
A32: =ROW()-1 -> 31 | B32: Trangnt | C32: Sangpn | D32: baodq004 | E32: 2205/2024/QĐ-ĐHM | F32: 07/06/2024 | G32: =(YEAR(H32)-YEAR(F32))*12 + MONTH(H32)-MONTH(F32) -> 72 | H32: 07/06/2030 | I32: =IF((H32-TODAY())<=0,"Kết thúc ĐT","Thời gian ĐT còn lại "&(H32-TODAY())&" ngày") -> Thời gian ĐT còn lại 1535 ngày | J32: 24C4102H3179 | K32: Đào Quốc Bảo | L32: Đào Quốc | M32: Bảo | N32: 26/02/1991 | O32: Nam | P32: 21 | Q32: ADNVT521 | R32: Kế toán | S32: =VLOOKUP(D32, 'Mail+SDT'!A357:C2472, 2, 0) -> 24C4102H3179@students.hou.edu.vn | T32: =VLOOKUP(D32, 'Mail+SDT'!$A$2:$C$2117, 3, 0) -> 399688474 | U32: DNVT | V32: Trường Trung cấp Vạn Tường | W32: ADNVT521 | X32: Kế toán | Z32: Trường Trung cấp Vạn Tường | AA32: Trực tuyến | AB32: HT | AC32: HT | AD32: HT | AG32: {=_xludf.XLOOKUP(D32,'Mail+SDT'!A:A,'Mail+SDT'!B:B)} -> #NAME? | AH32: {=_xludf.XLOOKUP(D32,'Mail+SDT'!A:A,'Mail+SDT'!C:C)} -> #NAME? | AI32: {=_xludf.XLOOKUP(D32,'ETK 3.2026'!I:I,'ETK 3.2026'!AF:AF)} -> #NAME?
A33: =ROW()-1 -> 32 | B33: Trangnt | C33: Quynhtnn | D33: baodt005 | E33: 2501/2024/QĐ-ĐHM | F33: 28/06/2024 | G33: =(YEAR(H33)-YEAR(F33))*12 + MONTH(H33)-MONTH(F33) -> 72 | H33: 28/06/2030 | I33: =IF((H33-TODAY())<=0,"Kết thúc ĐT","Thời gian ĐT còn lại "&(H33-TODAY())&" ngày") -> Thời gian ĐT còn lại 1556 ngày | J33: 24C4204D3684 | K33: Dương Thiên Bão | L33: Dương Thiên | M33: Bão | N33: 14/02/1995 | O33: Nam | P33: 21 | Q33: BDNP621 | R33: Quản trị kinh doanh | S33: =VLOOKUP(D33, 'Mail+SDT'!A152:C2267, 2, 0) -> 24C4204D3684@students.hou.edu.vn | T33: =VLOOKUP(D33, 'Mail+SDT'!$A$2:$C$2117, 3, 0) -> 944834979 | U33: DNP | V33: Trung tâm Đại học Mở Hà Nội tại Đà Nẵng | W33: BDNP621 | X33: Quản trị kinh doanh | Z33: Trung tâm Đại học Mở Hà Nội tại Đà Nẵng | AA33: Trực tuyến | AB33: HT | AC33: HT | AD33: HT | AG33: {=_xludf.XLOOKUP(D33,'Mail+SDT'!A:A,'Mail+SDT'!B:B)} -> #NAME? | AH33: {=_xludf.XLOOKUP(D33,'Mail+SDT'!A:A,'Mail+SDT'!C:C)} -> #NAME? | AI33: {=_xludf.XLOOKUP(D33,'ETK 3.2026'!I:I,'ETK 3.2026'!AF:AF)} -> #NAME?
A34: =ROW()-1 -> 33 | B34: Trangnt | C34: Sangpn | D34: baolq005 | E34: 2661/2024/QĐ-ĐHM | F34: 02/07/2024 | G34: =(YEAR(H34)-YEAR(F34))*12 + MONTH(H34)-MONTH(F34) -> 72 | H34: 02/07/2030 | I34: =IF((H34-TODAY())<=0,"Kết thúc ĐT","Thời gian ĐT còn lại "&(H34-TODAY())&" ngày") -> Thời gian ĐT còn lại 1560 ngày | J34: 24C1002H3977 | K34: Lê Quốc Bảo | L34: Lê Quốc | M34: Bảo | N34: 27/05/2001 | O34: Nam | P34: 21 | Q34: CDNVT621 | R34: Công nghệ thông tin | S34: =VLOOKUP(D34, 'Mail+SDT'!A528:C2643, 2, 0) -> 24C1002H3977@students.hou.edu.vn | T34: =VLOOKUP(D34, 'Mail+SDT'!$A$2:$C$2117, 3, 0) -> 345550916 | U34: DNVT | V34: Trường Trung cấp Vạn Tường | W34: CDNVT621 | X34: Công nghệ thông tin | Z34: Trường Trung cấp Vạn Tường | AA34: Trực tuyến | AB34: HT | AC34: HT | AD34: CBKL1 | AG34: {=_xludf.XLOOKUP(D34,'Mail+SDT'!A:A,'Mail+SDT'!B:B)} -> #NAME? | AH34: {=_xludf.XLOOKUP(D34,'Mail+SDT'!A:A,'Mail+SDT'!C:C)} -> #NAME? | AI34: {=_xludf.XLOOKUP(D34,'ETK 3.2026'!I:I,'ETK 3.2026'!AF:AF)} -> #NAME?
A35: =ROW()-1 -> 34 | B35: Trangnt | C35: Sangpn | D35: baonpn | E35: 2205/2024/QĐ-ĐHM | F35: 07/06/2024 | G35: =(YEAR(H35)-YEAR(F35))*12 + MONTH(H35)-MONTH(F35) -> 72 | H35: 07/06/2030 | I35: =IF((H35-TODAY())<=0,"Kết thúc ĐT","Thời gian ĐT còn lại "&(H35-TODAY())&" ngày") -> Thời gian ĐT còn lại 1535 ngày | J35: 24C4202H3158 | K35: Nguyễn Phúc Nguyên Bảo | L35: Nguyễn Phúc Nguyên | M35: Bảo | N35: 20/12/2001 | O35: Nam | P35: 21 | Q35: BDNVT621 | R35: Quản trị kinh doanh | S35: =VLOOKUP(D35, 'Mail+SDT'!A465:C2580, 2, 0) -> 24C4202H3158@students.hou.edu.vn | T35: =VLOOKUP(D35, 'Mail+SDT'!$A$2:$C$2117, 3, 0) -> 969600220 | U35: DNVT | V35: Trường Trung cấp Vạn Tường | W35: BDNVT621 | X35: Quản trị kinh doanh | Z35: Trường Trung cấp Vạn Tường | AA35: Trực tuyến | AB35: HT | AC35: HT | AD35: HT | AG35: {=_xludf.XLOOKUP(D35,'Mail+SDT'!A:A,'Mail+SDT'!B:B)} -> #NAME? | AH35: {=_xludf.XLOOKUP(D35,'Mail+SDT'!A:A,'Mail+SDT'!C:C)} -> #NAME? | AI35: {=_xludf.XLOOKUP(D35,'ETK 3.2026'!I:I,'ETK 3.2026'!AF:AF)} -> #NAME?
A36: =ROW()-1 -> 35 | B36: Trangnt | C36: Quynhtnn | D36: baont005 | E36: 833/2020/QĐ-ĐHM | F36: 10/03/2020 | G36: =(YEAR(H36)-YEAR(F36))*12 + MONTH(H36)-MONTH(F36) -> 96 | H36: 10/03/2028 | I36: =IF((H36-TODAY())<=0,"Kết thúc ĐT","Thời gian ĐT còn lại "&(H36-TODAY())&" ngày") -> Thời gian ĐT còn lại 716 ngày | J36: 20C-51-55.0-00720 | K36: Nguyễn Thế Bảo | L36: Nguyễn Thế | M36: Bảo | N36: 17/08/1996 | O36: Nam | P36: 13 | Q36: EDNP513 | R36: Luật kinh tế | S36: =VLOOKUP(D36, 'Mail+SDT'!A17:C2132, 2, 0) -> nguyenthebao1708@gmail.com | T36: =VLOOKUP(D36, 'Mail+SDT'!$A$2:$C$2117, 3, 0) -> 0 | U36: DNP | V36: Trung tâm Đại học Mở Hà Nội tại Đà Nẵng | W36: EDNP513 | X36: Luật kinh tế | Z36: Trung tâm Đại học Mở Hà Nội tại Đà Nẵng | AA36: Trực tuyến | AB36: HT | AC36: HT | AD36: HT | AF36: NỢ MÔN THI GHÉP THÁNG 4 TRẢ NỢ_TN 6.2026 | AG36: {=_xludf.XLOOKUP(D36,'Mail+SDT'!A:A,'Mail+SDT'!B:B)} -> #NAME? | AH36: {=_xludf.XLOOKUP(D36,'Mail+SDT'!A:A,'Mail+SDT'!C:C)} -> #NAME? | AI36: {=_xludf.XLOOKUP(D36,'ETK 3.2026'!I:I,'ETK 3.2026'!Z:Z)} -> #NAME?
A37: =ROW()-1 -> 36 | B37: Trangnt | C37: Quynhtnn | D37: benntc | E37: 980/2022/QĐ-ĐHM | F37: 07/04/2022 | G37: =(YEAR(H37)-YEAR(F37))*12 + MONTH(H37)-MONTH(F37) -> 72 | H37: 07/04/2028 | I37: =IF((H37-TODAY())<=0,"Kết thúc ĐT","Thời gian ĐT còn lại "&(H37-TODAY())&" ngày") -> Thời gian ĐT còn lại 744 ngày | J37: 22C7104D1171 | K37: Nguyễn Thanh Chí Bền | L37: Nguyễn Thanh Chí | M37: Bền | N37: 05/11/1997 | O37: Nam | P37: 17 | Q37: FDNP617 | R37: Ngôn ngữ Anh | S37: =VLOOKUP(D37, 'Mail+SDT'!A69:C2184, 2, 0) -> chiben262@gmail.com | T37: =VLOOKUP(D37, 'Mail+SDT'!$A$2:$C$2117, 3, 0) -> 905405041 | U37: DNP | V37: Trung tâm Đại học Mở Hà Nội tại Đà Nẵng | W37: FDNP617 | X37: Ngôn ngữ Anh | Z37: Trung tâm Đại học Mở Hà Nội tại Đà Nẵng | AA37: Trực tuyến | AB37: HT | AC37: HT | AD37: HT | AG37: {=_xludf.XLOOKUP(D37,'Mail+SDT'!A:A,'Mail+SDT'!B:B)} -> #NAME? | AH37: {=_xludf.XLOOKUP(D37,'Mail+SDT'!A:A,'Mail+SDT'!C:C)} -> #NAME? | AI37: {=_xludf.XLOOKUP(D37,'ETK 3.2026'!I:I,'ETK 3.2026'!Z:Z)} -> #NAME?
A38: =ROW()-1 -> 37 | B38: Trangnt | C38: Sangpn | D38: bienpq002 | E38: 2501/2024/QĐ-ĐHM | F38: 28/06/2024 | G38: =(YEAR(H38)-YEAR(F38))*12 + MONTH(H38)-MONTH(F38) -> 72 | H38: 28/06/2030 | I38: =IF((H38-TODAY())<=0,"Kết thúc ĐT","Thời gian ĐT còn lại "&(H38-TODAY())&" ngày") -> Thời gian ĐT còn lại 1556 ngày | J38: 24C1002H3653 | K38: Phan Quốc Biên | L38: Phan Quốc | M38: Biên | N38: 02/02/1990 | O38: Nam | P38: 21 | Q38: CDNVT621 | R38: Công nghệ thông tin | S38: =VLOOKUP(D38, 'Mail+SDT'!A553:C2668, 2, 0) -> 24C1002H3653@students.hou.edu.vn | T38: =VLOOKUP(D38, 'Mail+SDT'!$A$2:$C$2117, 3, 0) -> 357232232 | U38: DNVT | V38: Trường Trung cấp Vạn Tường | W38: CDNVT621 | X38: Công nghệ thông tin | Z38: Trường Trung cấp Vạn Tường | AA38: Trực tuyến | AB38: HT | AC38: HT | AD38: CBKL1 | AE38: BTH | AF38: Thiếu QT học phí để QR | AG38: {=_xludf.XLOOKUP(D38,'Mail+SDT'!A:A,'Mail+SDT'!B:B)} -> #NAME? | AH38: {=_xludf.XLOOKUP(D38,'Mail+SDT'!A:A,'Mail+SDT'!C:C)} -> #NAME? | AI38: {=_xludf.XLOOKUP(D38,'ETK 3.2026'!I:I,'ETK 3.2026'!AF:AF)} -> #NAME?
A39: =ROW()-1 -> 38 | B39: Trangnt | C39: Quynhtnn | D39: binhdv004 | E39: 1379/2024/QĐ-ĐHM | F39: 12/04/2024 | G39: =(YEAR(H39)-YEAR(F39))*12 + MONTH(H39)-MONTH(F39) -> 72 | H39: 12/04/2030 | I39: =IF((H39-TODAY())<=0,"Kết thúc ĐT","Thời gian ĐT còn lại "&(H39-TODAY())&" ngày") -> Thời gian ĐT còn lại 1479 ngày | J39: 24C1004D1882 | K39: Đồng Văn Bính | L39: Đồng Văn | M39: Bính | N39: 01/02/1989 | O39: Nam | P39: 21 | Q39: CDNP521 | R39: Công nghệ thông tin | S39: =VLOOKUP(D39, 'Mail+SDT'!A169:C2284, 2, 0) -> 24C1004D1882@students.hou.edu.vn | T39: =VLOOKUP(D39, 'Mail+SDT'!$A$2:$C$2117, 3, 0) -> 963757800 | U39: DNP | V39: Trung tâm Đại học Mở Hà Nội tại Đà Nẵng | W39: CDNP521 | X39: Công nghệ thông tin | Z39: Trung tâm Đại học Mở Hà Nội tại Đà Nẵng | AA39: Trực tuyến | AB39: HT | AC39: HT | AD39: CBKL1 | AG39: {=_xludf.XLOOKUP(D39,'Mail+SDT'!A:A,'Mail+SDT'!B:B)} -> #NAME? | AH39: {=_xludf.XLOOKUP(D39,'Mail+SDT'!A:A,'Mail+SDT'!C:C)} -> #NAME? | AI39: {=_xludf.XLOOKUP(D39,'ETK 3.2026'!I:I,'ETK 3.2026'!AF:AF)} -> #NAME?
A40: =ROW()-1 -> 39 | B40: Trangnt | C40: Sangpn | D40: binhpd004 | E40: 2661/2024/QĐ-ĐHM | F40: 02/07/2024 | G40: =(YEAR(H40)-YEAR(F40))*12 + MONTH(H40)-MONTH(F40) -> 72 | H40: 02/07/2030 | I40: =IF((H40-TODAY())<=0,"Kết thúc ĐT","Thời gian ĐT còn lại "&(H40-TODAY())&" ngày") -> Thời gian ĐT còn lại 1560 ngày | J40: 24C4502H4034 | K40: Phan Đức Bình | L40: Phan Đức | M40: Bình | N40: 24/06/1997 | O40: Nam | P40: 21 | Q40: DDNVT621 | R40: Tài chính - Ngân hàng | S40: =VLOOKUP(D40, 'Mail+SDT'!A589:C2704, 2, 0) -> 24C4502H4034@students.hou.edu.vn | T40: =VLOOKUP(D40, 'Mail+SDT'!$A$2:$C$2117, 3, 0) -> 355474692 | U40: DNVT | V40: Trường Trung cấp Vạn Tường | W40: DDNVT621 | X40: Tài chính - Ngân hàng | Z40: Trường Trung cấp Vạn Tường | AA40: Trực tuyến | AB40: HT | AC40: HT | AD40: CBKL1 | AE40: BTH | AF40: Thiếu QT học phí để QR | AG40: {=_xludf.XLOOKUP(D40,'Mail+SDT'!A:A,'Mail+SDT'!B:B)} -> #NAME? | AH40: {=_xludf.XLOOKUP(D40,'Mail+SDT'!A:A,'Mail+SDT'!C:C)} -> #NAME? | AI40: {=_xludf.XLOOKUP(D40,'ETK 3.2026'!I:I,'ETK 3.2026'!AF:AF)} -> #NAME?
...

Sheet ETK 3.2026
A1: STT | B1: Giáo vụ | C1: QLSV | D1: Trạm | E1: Khoá | F1: Ngành | G1: Mã sinh viên | H1: Lớp | I1: Tài khoản | J1: Họ | K1: Tên | L1: Ngày sinh | M1: Giới tính | N1: Thẩm định bằng | O1: Trạng thái xét CN T12/25 | P1: THÔNG TIN NHẬP HỌC | Q1: THỜI GIAN KẾT THÚC CHƯƠNG TRÌNH ĐÀO TẠO | U1: Loại TN | V1: Đợt xét ETK200 | W1: QLSV phản hồi nguyện vọng | X1: QLSV lấy nguyện vọng xét TN của SV | Y1: Điểm toàn khóa | Z1: Ghi chú điểm toàn khóa | AA1: Phản hồi của QLSV về điểm | AB1: Số tiền phải Tuy thu SV | AC1: QLSV điền chứng từ Truy thu | AF1: QLSV xác nhận chốt DS dự kiến đủ ĐK TN | AG1: SV đăng ký trên hệ thống | AH1: Quản lý | AI1: Ghi chú
P2: Thời gian QĐ đầu vào | Q2: Số TC MM | R2: Tháng học theo QĐ | S2: Thời gian TN theo QĐ | T2: TG chờ TN (số tháng) | AC2: Số tiền nộp | AD2: Số tham chiếu trên sao kê | AE2: Ngày nộp
A4: =IF(L4="","",COUNTA($L4:L$5)) -> 2 | B4: Hoangnm | C4: Khanhntk | D4: DNAV | E4: 17 | F4: A | G4: 22C4102E2243 | H4: ADNAV617 | I4: hiendtb | J4: Đoàn Thị Bích | K4: Hiền | L4: 30461 | M4: Nữ | N4: Hợp lệ | O4: HT | P4: 44712 | Q4: 0 | R4: 36 | S4: 45808 | T4: 0 | U4: A | V4: T3.26 | X4: Có nguyện vọng | Y4: Đã HTCT | AF4: Dự kiến đủ điều kiện | AH4: ĐN
A5: =IF(L5="","",COUNTA($L5:L$5)) -> 1 | B5: Hoangnm | C5: Khanhntk | D5: DNAV | E5: 17 | F5: B | G5: 22C4202E0249 | H5: BDNAV617 | I5: huongntt061 | J5: Nguyễn Thị Thanh | K5: Hương | L5: 34756 | M5: Nữ | N5: Hợp lệ | O5: HT | P5: 44624 | Q5: 0 | R5: 36 | S5: 45720 | T5: 0 | U5: A | V5: T3.26 | X5: Có nguyện vọng | Y5: Đã HTCT | AF5: Dự kiến đủ điều kiện | AH5: ĐN
A6: =IF(L6="","",COUNTA($L6:L$5)) -> 2 | B6: Hoangnm | C6: Khanhntk | D6: DNAV | E6: 17 | F6: B | G6: 22C4202E2239 | H6: BDNAV617 | I6: thuannd008 | J6: Nguyễn Đức | K6: Thuận | L6: 32597 | M6: Nam | N6: Hợp lệ | O6: HT | P6: 44712 | Q6: 0 | R6: 36 | S6: 45808 | T6: 0 | U6: A | V6: T3.26 | X6: Có nguyện vọng | Y6: Đã HTCT | AF6: Dự kiến đủ điều kiện | AH6: ĐN
A7: =IF(L7="","",COUNTA($L7:L$5)) -> 3 | B7: Hoangnm | C7: Khanhntk | D7: DNAV | E7: 17 | F7: B | G7: 22C4202E2884 | H7: BDNAV617 | I7: tranghp002 | J7: Huỳnh Phước | K7: Trạng | L7: 35907 | M7: Nam | N7: Chưa TĐB | O7: HT | P7: 44742 | Q7: 0 | R7: 36 | S7: 45838 | T7: 0 | U7: A | V7: T3.26 | X7: Có nguyện vọng | Y7: Đã HTCT | AF7: Dự kiến đủ điều kiện | AH7: ĐN
A8: =IF(L8="","",COUNTA($L8:L$5)) -> 4 | B8: Hoangnm | C8: Khanhntk | D8: DNAV | E8: 17 | F8: F | G8: 22C7102E2247 | H8: FDNAV617 | I8: tiendtt003 | J8: Dương Thị Thủy | K8: Tiên | L8: 31478 | M8: Nữ | N8: Hợp lệ | O8: HT | P8: 44712 | Q8: 0 | R8: 36 | S8: 45808 | T8: 0 | U8: A | V8: T3.26 | X8: Có nguyện vọng | Y8: Đã HTCT | AF8: Dự kiến đủ điều kiện | AH8: ĐN
A9: =IF(L9="","",COUNTA($L9:L$5)) -> 5 | B9: Hoangnm | C9: Khanhntk | D9: DNAV | E9: 17 | F9: H | G9: 22C5002E1847 | H9: HDNAV617 | I9: aunh | J9: Nguyễn Hải | K9: Âu | L9: 34629 | M9: Nam | N9: Hợp lệ | O9: HT | P9: 44698 | Q9: 0 | R9: 36 | S9: 45794 | T9: 0 | U9: A | V9: T3.26 | X9: Có nguyện vọng | Y9: Đã HTCT | AF9: Dự kiến đủ điều kiện | AH9: ĐN
A10: =IF(L10="","",COUNTA($L10:L$5)) -> 6 | B10: Hoangnm | C10: Khanhntk | D10: DNAV | E10: 17 | F10: H | G10: 22C5002E2248 | H10: HDNAV617 | I10: dinhpq002 | J10: Phạm Quang | K10: Định | L10: 30010 | M10: Nam | N10: Hợp lệ | O10: HT | P10: 44712 | Q10: 0 | R10: 36 | S10: 45808 | T10: 0 | U10: A | V10: T3.26 | X10: Có nguyện vọng | Y10: Nợ môn_Không TN | Z10: EL14 | AF10: Không đủ điều kiện | AH10: ĐN
A11: =IF(L11="","",COUNTA($L11:L$5)) -> 7 | B11: Hoangnm | C11: Khanhntk | D11: DNAV | E11: 17 | F11: H | G11: 22C5002E2249 | H11: HDNAV617 | I11: ducpnm | J11: Phú Nguyễn Minh | K11: Đức | L11: 34186 | M11: Nam | N11: Hợp lệ | O11: HT | P11: 44712 | Q11: 0 | R11: 36 | S11: 45808 | T11: 0 | U11: A | V11: T3.26 | X11: Có nguyện vọng | Y11: Đã HTCT | AF11: Dự kiến đủ điều kiện | AH11: ĐN
A12: =IF(L12="","",COUNTA($L12:L$5)) -> 8 | B12: Hoangnm | C12: Khanhntk | D12: DNAV | E12: 17 | F12: H | G12: 22C5002E0490 | H12: HDNAV417 | I12: nguyetltt | J12: Lê Thị Thu | K12: Nguyệt | L12: 35409 | M12: Nữ | N12: Chưa TĐB | O12: HT | P12: 44641 | Q12: 20 | R12: 30 | S12: 45556 | T12: 0 | U12: A | V12: KH CŨ | X12: Có nguyện vọng | Y12: Nợ môn_Không TN | Z12: Nợ nhiều | AF12: Không đủ điều kiện | AH12: ĐN
A13: =IF(L13="","",COUNTA($L13:L$5)) -> 9 | B13: Hoangnm | C13: Khanhntk | D13: DNCN | E13: 17 | F13: H | G13: 22C5002J1029 | H13: HDNCN617 | I13: sondk | J13: Đào Kim | K13: Sơn | L13: 34692 | M13: Nam | N13: Hợp lệ | O13: HT | P13: 44650 | Q13: 0 | R13: 36 | S13: 45746 | T13: 0 | U13: A | V13: T3.26 | X13: Có nguyện vọng | Y13: Đã HTCT | AF13: Dự kiến đủ điều kiện | AH13: ĐN
A14: =IF(L14="","",COUNTA($L14:L$5)) -> 10 | B14: Hoangnm | C14: Khanhntk | D14: QB | E14: 18 | F14: F | G14: 22C7131D5099 | H14: FQB318 | I14: huyenttt013 | J14: Trần Thị Thúy | K14: Huyền | L14: 36469 | M14: Nữ | N14: Hợp lệ | O14: HT | P14: 44865 | Q14: 16 | R14: 31 | S14: 45808 | T14: 0 | U14: A | V14: KH CŨ | X14: Có nguyện vọng | Y14: Nợ môn_Không TN | Z14: EN56,EN48,EN37 | AF14: Không đủ điều kiện | AH14: ELC
A15: =IF(L15="","",COUNTA($L15:L$5)) -> 11 | B15: Hungnc | C15: Khanhntk | D15: DNDH | E15: 17 | F15: H | G15: 22C5036D2268 | H15: HDNDH617 | I15: hoailv | J15: Lê Văn | K15: Hoài | L15: 33455 | M15: Nam | N15: Chưa TĐB | O15: HT | P15: 44712 | R15: 36 | S15: 45808 | T15: 0 | U15: A | V15: T3.26 | X15: Có nguyện vọng | Y15: Đã HTCT | AF15: Dự kiến đủ điều kiện | AH15: ĐN
A16: =IF(L16="","",COUNTA($L16:L$5)) -> 12 | B16: Hungnc | C16: Khanhntk | D16: DNDH | E16: 17 | F16: H | G16: 22C5036D2893 | H16: HDNDH617 | I16: quynhnh003 | J16: Nguyễn Hữu | K16: Quỳnh | L16: 31769 | M16: Nam | N16: Chưa TĐB | O16: HT | P16: 44742 | R16: 36 | S16: 45838 | T16: 0 | U16: A | V16: T3.26 | X16: Có nguyện vọng | Y16: Nợ môn_Không TN | AF16: Không đủ điều kiện | AH16: ĐN
A17: =IF(L17="","",COUNTA($L17:L$5)) -> 13 | B17: Hungnc | C17: Khanhntk | D17: DNKH | E17: 17 | F17: B | G17: 22C4241E1235 | H17: BDNKH217 | I17: namdx | J17: Đặng Xuân | K17: Nam | L17: 29146 | M17: Nam | N17: Chờ hoàn thiện | O17: HTCT | P17: 44658 | Q17: 40 | R17: 24 | S17: 45419 | T17: 0 | U17: A | V17: KH CŨ | X17: Có nguyện vọng | Y17: Đã HTCT | AF17: Dự kiến đủ điều kiện | AH17: ĐN
A18: =IF(L18="","",COUNTA($L18:L$5)) -> 14 | B18: Hungnc | C18: Khanhntk | D18: DNKH | E18: 17 | F18: C | G18: 22C1041E1037 | H18: CDNKH617 | I18: namvh011 | J18: Võ Hùng | K18: Nam | L18: 34354 | M18: Nam | N18: Hợp lệ | O18: HT | P18: 44650 | R18: 36 | S18: 45746 | T18: 0 | U18: A | V18: T3.26 | X18: Có nguyện vọng | Y18: Đã HTCT | AF18: Dự kiến đủ điều kiện | AH18: ĐN
A19: =IF(L19="","",COUNTA($L19:L$5)) -> 15 | B19: Hungnc | C19: Khanhntk | D19: DNKH | E19: 17 | F19: C | G19: 22C1041E1039 | H19: CDNKH617 | I19: trinhnv003 | J19: Nguyễn Văn | K19: Trình | L19: 30857 | M19: Nam | N19: Hợp lệ | O19: HT | P19: 44650 | R19: 36 | S19: 45746 | T19: 0 | U19: A | V19: T3.26 | X19: Có nguyện vọng | Y19: Đã HTCT | AF19: Dự kiến đủ điều kiện | AH19: ĐN
A20: =IF(L20="","",COUNTA($L20:L$5)) -> 16 | B20: Hungnc | C20: Khanhntk | D20: DNKH | E20: 17 | F20: F | G20: 22C7141E3380 | H20: FDNKH617 | I20: trungnqa | J20: Nguyễn Quốc Anh | K20: Trung | L20: 27582 | M20: Nam | N20: Hợp lệ | O20: HT | P20: 44778 | R20: 36 | S20: 45874 | T20: 0 | U20: A | V20: T3.26 | X20: Có nguyện vọng | Y20: Đã HTCT | AF20: Dự kiến đủ điều kiện | AH20: ĐN
A21: =IF(L21="","",COUNTA($L21:L$5)) -> 17 | B21: Hungnc | C21: Khanhntk | D21: DNNT | E21: 17 | F21: B | G21: 22C4245D2356 | H21: BDNNT517 | I21: tuanqm | J21: Quảng Minh | K21: Tuấn | L21: 35539 | M21: Nam | N21: Hợp lệ | O21: HT | P21: 44715 | R21: 36 | S21: 45811 | T21: 0 | U21: A | V21: KH CŨ | X21: Có nguyện vọng | Y21: Đã HTCT | AF21: Dự kiến đủ điều kiện | AH21: ĐN
A22: =IF(L22="","",COUNTA($L22:L$5)) -> 18 | B22: Hungnc | C22: Khanhntk | D22: SG | E22: 17 | F22: A | G22: 22C4102D0458 | H22: ASG517 | I22: oanhdtk009 | J22: Đinh Thị Kim | K22: Oanh | L22: 35609 | M22: Nữ | N22: Chưa TĐB | O22: HT | P22: 44641 | R22: 36 | S22: 45737 | T22: 0 | U22: A | V22: KH CŨ | X22: Có nguyện vọng | Y22: Nợ môn_Không TN | Z22: AC11,EG09.3 | AF22: Không đủ điều kiện | AH22: ELC
A23: =IF(L23="","",COUNTA($L23:L$5)) -> 19 | B23: Hungnc | C23: Khanhntk | D23: SG | E23: 17 | F23: B | G23: 22C4202D3285 | H23: BSG617 | I23: hanhnt049 | J23: Nguyễn Thị | K23: Hạnh | L23: 33440 | M23: Nữ | N23: Hợp lệ | O23: HT | P23: 44771 | R23: 36 | S23: 45867 | T23: 0 | U23: A | V23: T3.26 | X23: Có nguyện vọng | Y23: Đã HTCT | AF23: Dự kiến đủ điều kiện | AH23: ELC
A24: =IF(L24="","",COUNTA($L24:L$5)) -> 20 | B24: Hungnc | C24: Khanhntk | D24: SG | E24: 17 | F24: C | G24: 21C-10-48.1-01465 | H24: CSG117 | I24: trungpnh | J24: Phan Nguyễn Hoài | K24: Trung | L24: 35694 | M24: Nam | N24: Chưa TĐB | O24: HT | P24: 44292 | Q24: 0 | R24: 43 | S24: 45602 | T24: 0 | U24: A | V24: KH CŨ | X24: Có nguyện vọng | Y24: Nợ môn_Không TN | Z24: EG43,IT11,IT59,IT60 | AF24: Không đủ điều kiện | AH24: ELC
A25: =IF(L25="","",COUNTA($L25:L$5)) -> 21 | B25: Hungnc | C25: Khanhntk | D25: SG | E25: 17 | F25: F | G25: 22C7102D3182 | H25: FSG517 | I25: mopt003 | J25: Phạm Thị | K25: Mơ | L25: 33742 | M25: Nữ | N25: Chưa TĐB | O25: HT | P25: 44753 | Q25: 13 | R25: 32 | S25: 45727 | T25: 0 | U25: A | V25: KH CŨ | X25: Có nguyện vọng | Y25: Nợ môn_Không TN | AF25: Không đủ điều kiện | AH25: ELC
A26: =IF(L26="","",COUNTA($L26:L$5)) -> 22 | B26: Hungnc | C26: Khanhntk | D26: SG | E26: 17 | F26: G | G26: 22C4602D2961 | H26: GSG317 | I26: hana | J26: Ngô An | K26: Hạ | L26: 28485 | M26: Nam | N26: Chưa TĐB | O26: HT | P26: 44748 | Q26: 24 | R26: 35 | S26: 45814 | T26: 0 | U26: A | V26: KH CŨ | X26: Có nguyện vọng | Y26: Nợ môn_Không TN | AF26: Không đủ điều kiện | AH26: ELC
A27: =IF(L27="","",COUNTA($L27:L$5)) -> 23 | B27: Hungnc | C27: Khanhntk | D27: SG | E27: 18 | F27: B | G27: 22C4202D4749 | H27: BSG418 | I27: khoant002 | J27: Nguyễn Tấn | K27: Khoa | L27: 31050 | M27: Nam | N27: Hợp lệ | O27: HT | P27: 44841 | Q27: 11 | R27: 33 | S27: 45845 | T27: 0 | U27: A | V27: T3.26 | X27: Có nguyện vọng | Y27: Đã HTCT | AF27: Dự kiến đủ điều kiện | AH27: ELC
A28: =IF(L28="","",COUNTA($L28:L$5)) -> 24 | B28: Hungnc | C28: Khanhntk | D28: SG | E28: 18 | F28: B | G28: 22C4202D5718 | H28: BSG418 | I28: thaitm | J28: Trương Minh | K28: Thái | L28: 33103 | M28: Nam | N28: Hợp lệ | O28: HT | P28: 44918 | Q28: 17 | R28: 31 | S28: 45861 | T28: 0 | U28: A | V28: T3.26 | X28: Có nguyện vọng | Y28: Nợ môn_Không TN | AF28: Không đủ điều kiện | AH28: ELC
A29: =IF(L29="","",COUNTA($L29:L$5)) -> 25 | B29: Hungnc | C29: Khanhntk | D29: SG | E29: 18 | F29: C | G29: 22C1002D5596 | H29: CSG418 | I29: duynt012 | J29: Nguyễn Thanh | K29: Duy | L29: 36365 | M29: Nam | N29: Hợp lệ | O29: HT | P29: 44908 | Q29: 11 | R29: 33 | S29: 45913 | T29: 0 | U29: A | V29: T3.26 | X29: Có nguyện vọng | Y29: Nợ môn_Không TN | AF29: Không đủ điều kiện | AH29: ELC
A30: =IF(L30="","",COUNTA($L30:L$5)) -> 26 | B30: Hungnc | C30: Khanhntk | D30: SG | E30: 18 | F30: C | G30: 22C1002D4729 | H30: CSG418 | I30: minhhn003 | J30: Hoàng Ngọc | K30: Minh | L30: 33644 | M30: Nam | N30: Hợp lệ | O30: HT | P30: 44841 | Q30: 10 | R30: 33 | S30: 45845 | T30: 0 | U30: A | V30: T3.26 | X30: Có nguyện vọng | Y30: Nợ môn_Không TN | Z30: IT40,IT43 | AF30: Không đủ điều kiện | AH30: ELC
A31: =IF(L31="","",COUNTA($L31:L$5)) -> 27 | B31: Hungnc | C31: Khanhntk | D31: SG | E31: 18 | F31: D | G31: 22C4502D2962 | H31: DSG418 | I31: thamtq | J31: Trương Quế | K31: Thắm | L31: 32874 | M31: Nữ | N31: Hợp lệ | O31: HT | P31: 44748 | R31: 36 | S31: 45844 | T31: 0 | U31: A | V31: T3.26 | X31: Có nguyện vọng | Y31: Đã HTCT | AF31: Dự kiến đủ điều kiện | AH31: ELC
A32: =IF(L32="","",COUNTA($L32:L$5)) -> 28 | B32: Hungnc | C32: Khanhntk | D32: SG | E32: 18 | F32: F | G32: 19C-71-48.1-02646 | H32: FSG118 | I32: cuongtt002 | J32: Trần Tuấn | K32: Cường | L32: 28591 | M32: Nam | N32: Hợp lệ | O32: HT | P32: 43706 | Q32: 0 | R32: 36 | S32: 44802 | T32: 0 | U32: A | V32: KH CŨ | X32: Có nguyện vọng | Y32: Nợ môn_Không TN | AF32: Không đủ điều kiện | AH32: ELC
A33: =IF(L33="","",COUNTA($L33:L$5)) -> 29 | B33: Hungnc | C33: Khanhntk | D33: SG | E33: 18 | F33: F | G33: 22C7102D5592 | H33: FSG418 | I33: nghianm004 | J33: Nguyễn Minh | K33: Nghĩa | L33: 30740 | M33: Nữ | N33: Hợp lệ | O33: HT | P33: 44908 | Q33: 11 | R33: 33 | S33: 45913 | T33: 0 | U33: A | V33: T3.26 | X33: Có nguyện vọng | Y33: Nợ môn_Không TN | Z33: EN39 | AF33: Không đủ điều kiện | AH33: ELC
A34: =IF(L34="","",COUNTA($L34:L$5)) -> 30 | B34: Hungnc | C34: Khanhntk | D34: SG | E34: 18 | F34: F | G34: 23C7101G0012 | H34: FSG418 | I34: phuongnv015 | J34: Nguyễn Văn | K34: Phương | L34: 30801 | M34: Nam | N34: Chưa TĐB | O34: HT | P34: 44967 | Q34: 18 | R34: 31 | S34: 45904 | T34: 0 | U34: A | V34: T3.26 | X34: Có nguyện vọng | Y34: Nợ môn_Không TN | Z34: EN39 | AF34: Không đủ điều kiện | AH34: ELC
A35: =IF(L35="","",COUNTA($L35:L$5)) -> 31 | B35: Hungnc | C35: Khanhntk | D35: SG | E35: 18 | F35: H | G35: 21C-50-48.1-04223 | H35: HSG418 | I35: hungdt004 | J35: Đinh Thái | K35: Hùng | L35: 30713 | M35: Nam | N35: Hợp lệ | O35: HT | P35: 44379 | R35: 36 | S35: 45475 | T35: 0 | U35: A | V35: T3.26 | X35: Có nguyện vọng | Y35: Nợ môn_Không TN | AF35: Không đủ điều kiện | AH35: ELC
A36: =IF(L36="","",COUNTA($L36:L$5)) -> 32 | B36: Hungnc | C36: Khanhntk | D36: SG | E36: 18 | F36: H | G36: 23C5002D0025 | H36: HSG418 | I36: nangcms | J36: Chau Meas Som | K36: Nang | L36: 33100 | M36: Nam | N36: Hợp lệ | O36: HT | P36: 44967 | R36: 36 | S36: 46057 | T36: 0 | U36: A | V36: T3.26 | X36: Có nguyện vọng | Y36: Nợ môn_Không TN | AF36: Không đủ điều kiện | AH36: ELC
A37: =IF(L37="","",COUNTA($L37:L$5)) -> 33 | B37: Hungnc | C37: Khanhntk | D37: SG | E37: 18 | F37: H | G37: 22C5002D4743 | H37: HSG418 | I37: yenbk | J37: Bùi Kim | K37: Yến | L37: 30966 | M37: Nữ | N37: Hợp lệ | O37: HT | P37: 44841 | Q37: 11 | R37: 33 | S37: 45845 | T37: 0 | U37: A | V37: T3.26 | X37: Có nguyện vọng | Y37: Đã HTCT | AF37: Dự kiến đủ điều kiện | AH37: ELC
A38: =IF(L38="","",COUNTA($L38:L$5)) -> 34 | B38: Hungnc | C38: Khanhntk | D38: SG | E38: 19 | F38: B | G38: 23C4202D1332 | H38: BSG219 | I38: trangbtt006 | J38: Bùi Thị Thu | K38: Trang | L38: 34211 | M38: Nữ | N38: Hợp lệ | O38: HT | P38: 45016 | Q38: 20 | R38: 30 | S38: 45904 | T38: 0 | U38: A | V38: T3.26 | X38: Có nguyện vọng | Y38: Đã HTCT | AF38: Dự kiến đủ điều kiện | AH38: ELC
A39: =IF(L39="","",COUNTA($L39:L$5)) -> 35 | B39: Hungnc | C39: Khanhntk | D39: SG | E39: 19 | F39: C | G39: 23C1002D1398 | H39: CSG219 | I39: duyntm | J39: Nguyễn Trần Minh | K39: Duy | L39: 35431 | M39: Nam | N39: Hợp lệ | O39: HT | P39: 45023 | Q39: 23 | R39: 29 | S39: 45904 | T39: 0 | U39: A | V39: T3.26 | X39: Có nguyện vọng | Y39: Nợ môn_Không TN | AF39: Không đủ điều kiện | AH39: ELC
A40: =IF(L40="","",COUNTA($L40:L$5)) -> 36 | B40: Hungnc | C40: Khanhntk | D40: SG | E40: 19 | F40: E | G40: 23C5102D1178 | H40: ESG219 | I40: anhntt023 | J40: Nguyễn Thị Tú | K40: Anh | L40: 28689 | M40: Nữ | N40: Hợp lệ | O40: HT | P40: 45016 | Q40: 20 | R40: 30 | S40: 45904 | T40: 0 | U40: A | V40: T3.26 | X40: Có nguyện vọng | Y40: Đã HTCT | AF40: Dự kiến đủ điều kiện | AH40: ELC
A41: =IF(L41="","",COUNTA($L41:L$5)) -> 37 | B41: Hungnc | C41: Khanhntk | D41: SG | E41: 19 | F41: F | G41: 23C7102D0898 | H41: FSG219 | I41: sangnv009 | J41: Nguyễn Viết | K41: Sang | L41: 31925 | M41: Nam | N41: Chưa TĐB | O41: HT | P41: 44999 | Q41: 16 | R41: 31 | S41: 45934 | T41: 0 | U41: A | V41: T3.26 | X41: Có nguyện vọng | Y41: Nợ môn_Không TN | AF41: Không đủ điều kiện | AH41: ELC
...

Sheet CHECK ĐƠN T12.2025
A1: STT | B1: Quản lý sinh viên | C1: Giáo vụ | D1: Tài khoản | E1: Mã sinh viên | F1: Họ và tên đệm | G1: Tên | H1: Ngày sinh | I1: Giới tính | J1: Khóa | K1: Tên lớp | L1: Tên ngành | M1: Đơn vị phối hợp (Mã đơn vị) | N1: Tên đơn vị phối hợp | O1: Trạng thái QLSV dự kiến T12/2025 | P1: Đã có đơn scan | Q1: Bản cứng | R1: Trường hợp trước 10h sáng mai chưa có bản cứng. Tự cá nhân QLSV báo cáo Ban Lãnh đạo Viện.
A2: 1 | B2: Anhlt | C2: Quynhtnn | D2: lamvn | E2: 20C-50-55.0-03293 | F2: Võ Ngọc | G2: Lâm | H2: 31924 | I2: Nam | J2: 13 | K2: HDNP513 | L2: Luật | M2: DNP | N2: Trung tâm Đại học Mở Hà Nội tại Đà Nẵng | O2: TH | P2: x
A3: 2 | B3: Anhlt | C3: Sangpn | D3: hienhh002 | E3: 21C7102H0573 | F3: Hồ Hữu | G3: Hiền | H3: 33867 | I3: Nam | J3: 16 | K3: FDNVT516 | L3: Ngôn ngữ Anh | M3: DNVT | N3: Trường Trung cấp Vạn Tường | O3: TH | P3: x
A4: 3 | B4: Anhlt | C4: Sangpn | D4: locddx | E4: 21C-50-55.4-04204 | F4: Đặng Đoàn Xuân | G4: Lộc | H4: 29855 | I4: Nữ | J4: 16 | K4: HDNVT516 | L4: Luật | M4: DNVT | N4: Trường Trung cấp Vạn Tường | O4: TH | P4: x
A5: 4 | B5: Hungdv | C5: Trinhptt | D5: 24C7201P1189 | E5: 24C7201P1189 | F5: Bùi Thị | G5: Phượng | H5: 36979 | I5: Nữ | K5: TQ24(CĐCT) | L5: Ngôn ngữ Trung Quốc | M5: TX - KTM | N5: Trường Trung cấp Kinh tế, Kỹ thuật, Thương mại | O5: TH | P5: x | Q5: x
A6: 5 | B6: Huongdt | C6: Dungnt | D6: hanght013 | E6: 23C4119D5004 | F6: Hoàng Thị | G6: Hằng | H6: 34294 | I6: Nữ | J6: 20 | K6: ABN520 | L6: Kế toán | M6: BN | N6: Trung tâm GDTX Bắc Ninh | O6: TH | P6: x | Q6: x
A7: 6 | B7: Huongdt | C7: Nhungntt | D7: trangntt097 | E7: 24C4101U5492 | F7: Nguyễn Thị Thu | G7: Trang | H7: 36433 | I7: Nữ | J7: 22 | K7: AKTM422 | L7: Kế toán | M7: KTM | N7: Trường Trung cấp Kinh tế, Kỹ thuật, Thương mại | O7: TH | P7: x
A8: 7 | B8: Huongdt | C8: Nhungntt | D8: minhln014 | E8: 24C1001U8108 | F8: Lê Nho | G8: Minh | H8: 34717 | I8: Nam | J8: 22 | K8: CKTM422 | L8: Công nghệ thông tin | M8: KTM | N8: Trường Trung cấp Kinh tế, Kỹ thuật, Thương mại | O8: TH | P8: x | Q8: x
A9: 8 | B9: Huongdt | C9: Nhungntt | D9: toanbs | E9: 24C1001U7788 | F9: Bùi Song | G9: Toàn | H9: 33317 | I9: Nam | J9: 22 | K9: CKTM622 | L9: Công nghệ thông tin | M9: KTM | N9: Trường Trung cấp Kinh tế, Kỹ thuật, Thương mại | O9: TH | P9: x | Q9: x
A10: 9 | B10: Huongdt | C10: Nhungntt | D10: mailt018 | E10: 24C7201U4857 | F10: Lê Thị | G10: Mai | H10: 38076 | I10: Nữ | J10: 22 | K10: OKTM422 | L10: Ngôn ngữ Trung Quốc | M10: KTM | N10: Trường Trung cấp Kinh tế, Kỹ thuật, Thương mại | O10: TH | P10: x
A11: 10 | B11: Huongdt | C11: Nhungntt | D11: maint060 | E11: 24C7201U4856 | F11: Nguyễn Thị | G11: Mai | H11: 38001 | I11: Nữ | J11: 22 | K11: OKTM422 | L11: Ngôn ngữ Trung Quốc | M11: KTM | N11: Trường Trung cấp Kinh tế, Kỹ thuật, Thương mại | O11: TH | P11: x
A12: 11 | B12: Huongdt | C12: Nhungntt | D12: mytlt | E12: 24C7201U5481 | F12: Trương Lê Trà | G12: My | H12: 38960 | I12: Nữ | J12: 22 | K12: OKTM522 | L12: Ngôn ngữ Trung Quốc | M12: KTM | N12: Trường Trung cấp Kinh tế, Kỹ thuật, Thương mại | O12: TH | P12: x | Q12: x
A13: 12 | B13: Huongdt | C13: Ngocnt | D13: tuyetdt012 | E13: 21C5001H1438 | F13: Đoàn Thị | G13: Tuyết | H13: 26758 | I13: Nữ | J13: 16 | K13: HHTM516 | L13: Luật | M13: NT | N13: Trường Trung cấp Ngoại thương | O13: TH | P13: x | Q13: x
A14: 13 | B14: Huongdt | C14: Ngocnt | D14: andt011 | E14: 24C4101S8261 | F14: Đỗ Thị | G14: Ân | H14: 29230 | I14: Nữ | J14: 22 | K14: ANT522 | L14: Kế toán | M14: NT | N14: Trường Trung cấp Ngoại thương | O14: TH | P14: x | Q14: x
A15: 14 | B15: Huongdt | C15: Ngocnt | D15: quyetlv004 | E15: 24C1001S8232 | F15: Lê Văn | G15: Quyết | H15: 37146 | I15: Nam | J15: 22 | K15: CNT522 | L15: Công nghệ thông tin | M15: NT | N15: Trường Trung cấp Ngoại thương | O15: TH | P15: x | Q15: x
A16: 15 | B16: Huongdt | C16: Ngocnt | D16: loanntb002 | E16: 24C7101S7338 | F16: Nguyễn Thị Bích | G16: Loan | H16: 29953 | I16: Nữ | J16: 22 | K16: FNT322 | L16: Ngôn ngữ Anh | M16: NT | N16: Trường Trung cấp Ngoại thương | O16: TH | P16: x
A17: 16 | B17: Huongdt | C17: Ngocnt | D17: hangttt026 | E17: 24C7101S7346 | F17: Tạ Thị Thanh | G17: Hằng | H17: 37762 | I17: Nữ | J17: 22 | K17: FNT322 | L17: Ngôn ngữ Anh | M17: NT | N17: Trường Trung cấp Ngoại thương | O17: TH | P17: x | Q17: x
